Workbook

Sheet step2_raw_simulation
A1: Persona_ID | B1: Run_ID | C1: Used_Seed | D1: Gender | E1: Age | F1: Region | G1: Education | H1: Employment | I1: Income_Mil | J1: Dependents | K1: AI_ENF1_Score | L1: Human_ENF1 | M1: Delta_ENF1 | N1: AI_ENF1_Reason | O1: Human_ENF1_Reason | P1: AI_ENF2_Score | Q1: Human_ENF2 | R1: Delta_ENF2 | S1: AI_ENF2_Reason | T1: Human_ENF2_Reason | U1: AI_FAC1_Score | V1: Human_FAC1 | W1: Delta_FAC1 | X1: AI_FAC1_Reason | Y1: Human_FAC1_Reason | Z1: AI_FAC2_Score | AA1: Human_FAC2 | AB1: Delta_FAC2 | AC1: AI_FAC2_Reason | AD1: Human_FAC2_Reason | AE1: AI_TRU1_Score | AF1: Human_TRU1 | AG1: Delta_TRU1 | AH1: AI_TRU1_Reason | AI1: Human_TRU1_Reason | AJ1: AI_TRU2_Score | AK1: Human_TRU2 | AL1: Delta_TRU2 | AM1: AI_TRU2_Reason | AN1: Human_TRU2_Reason | AO1: AI_TRU3_Score | AP1: Human_TRU3 | AQ1: Delta_TRU3 | AR1: AI_TRU3_Reason | AS1: Human_TRU3_Reason | AT1: AI_TRU4_Score | AU1: Human_TRU4 | AV1: Delta_TRU4 | AW1: AI_TRU4_Reason | AX1: Human_TRU4_Reason | AY1: AI_OUT1_Score | AZ1: Human_OUT1 | BA1: Delta_OUT1 | BB1: AI_OUT1_Reason | BC1: Human_OUT1_Reason
A2: 1 | B2: 1 | C2: 43 | D2: Nữ | E2: 30 - 39 | F2: Thành thị | G2: Sau Đại học | H2: Chính thức | I2: 27.5 | J2: 1 | K2: 4 | L2: 5 | M2: 1 | N2: Chưa thấy nhiều thay đổi về các chế tài pháp lý hay xử phạt, chỉ dừng lại ở việc giảm bậc thuế. | O2: Các thay đổi hiện tại chỉ mới dừng lại ở việc giảm bậc thuế, giúp người đóng thuế cảm thấy đơn giản và nhẹ gánh trong việc đóng thuế TNCN. Chưa thấy nhiều thay đổi về các chế tài pháp lý hay xử phạt. | P2: 3 | Q2: 5 | R2: 2 | S2: Cơ quan thuế chưa thực sự có khả năng và công nghệ để phát hiện trốn thuế hiệu quả. | T2: Đồng ý. Quan trọng là cơ quan thuế có muốn thực thi hay không. | U2: 4 | V2: 1 | W2: -3 | X2: Form khai báo/phản ánh không đồng bộ, thông tin liên hệ không đầy đủ, hỗ trợ hạn chế. | Y2: Form khai báo/phản ánh không đồng bộ, thông tin liên hệ không có, không có người tiếp nhận, hỗ trợ. Phần mềm eTax cũng không có phản hồi người nộp thuế. Người khai báo thuế gặp vấn đề bị người khác sử dụng CCCD để đăng ký mã số thuế tại 1 DN không làm việc mà cơ quan thuế không biết/không xử lý dù đã phản ánh nhiều lần. | Z2: 7 | AA2: 10 | AB2: 3 | AC2: Phương án mới đơn giản hơn so với trước đây nhưng vẫn còn phức tạp về mặt thủ tục và tính toán. | AD2: Hoàn toàn đồng ý vì trước đây 7 bậc là quá nhiều, khó để tính toán. | AE2: 4 | AF2: 5 | AG2: 1 | AH2: Chưa có chế tài pháp lý mạnh mẽ nên lòng tin vào việc thực thi chính sách chưa cao. | AI2: Các thay đổi hiện tại chỉ mới dừng lại ở việc giảm bậc thuế, giúp người đóng thuế cảm thấy đơn giản và nhẹ gánh trong việc đóng thuế TNCN. Chưa thấy nhiều thay đổi về các chế tài pháp lý hay xử phạt. | AJ2: 9 | AK2: 10 | AL2: 1 | AM2: Mức thuế mới công bằng, phù hợp với thu nhập hiện tại của tôi. | AN2: Vì theo chính sách mới, tôi không phải đóng thuế nữa. Hoàn toàn đồng ý. | AO2: 8 | AP2: 5 | AQ2: -3 | AR2: Thuê đóng góp cho sự phát triển quốc gia và dịch vụ công như y tế, đường xá... | AS2: Khi nào các chính sách chế tài được xử lý nghiêm, giải quyết vấn đề tham nhũng thì lòng tin của tôi sẽ cao hơn. | AT2: 7 | AU2: 10 | AV2: 3 | AW2: Đã giải thích rõ ràng về mục tiêu cải cách thuế nhưng còn nhiều câu hỏi chưa được trả lời. | AX2: Hoàn toàn đồng ý về việc truyền thông và giải thích của Chính phủ. | AY2: 8 | AZ2: 9 | BA2: 1 | BB2: Nhìn chung, vì chính sách mới giúp tôi không phải đóng thuế nữa nên mức độ ủng hộ cao. Tuy nhiên, lòng tin vào thực thi chế tài pháp lý vẫn còn thấp. | BC2: Ủng hộ việc giảm bậc, tăng mức giảm trừ gia cảnh nhưng niềm tin về việc thực thi chính sách thì không cao cho đến khi việc thực thi các chế tài là rõ ràng, minh bạch, nghiêm khắc. Nhìn chung, vì chính sách mới giúp tôi không phải đóng thuế nữa nên mức độ ủng hộ cao.
A3: 1 | B3: 2 | C3: 44 | D3: Nữ | E3: 30 - 39 | F3: Thành thị | G3: Sau Đại học | H3: Chính thức | I3: 27.5 | J3: 1 | K3: 3 | L3: 5 | M3: 2 | N3: Chưa thấy nhiều thay đổi về các chế tài pháp lý hay xử phạt, chỉ giảm bậc thuế. | O3: Các thay đổi hiện tại chỉ mới dừng lại ở việc giảm bậc thuế, giúp người đóng thuế cảm thấy đơn giản và nhẹ gánh trong việc đóng thuế TNCN. Chưa thấy nhiều thay đổi về các chế tài pháp lý hay xử phạt. | P3: 4 | Q3: 5 | R3: 1 | S3: Cơ quan thuế có đủ khả năng và công nghệ để phát hiện nhưng thực tế chưa rõ ràng. | T3: Đồng ý. Quan trọng là cơ quan thuế có muốn thực thi hay không. | U3: 3 | V3: 1 | W3: -2 | X3: Form khai báo/phản ánh không đồng bộ, thông tin liên hệ không có, hỗ trợ hạn chế. | Y3: Form khai báo/phản ánh không đồng bộ, thông tin liên hệ không có, không có người tiếp nhận, hỗ trợ. Phần mềm eTax cũng không có phản hồi người nộp thuế. Người khai báo thuế gặp vấn đề bị người khác sử dụng CCCD để đăng ký mã số thuế tại 1 DN không làm việc mà cơ quan thuế không biết/không xử lý dù đã phản ánh nhiều lần. | Z3: 9 | AA3: 10 | AB3: 1 | AC3: Đơn giản hóa biểu thuế giúp dễ dàng tính toán hơn so với trước đây. | AD3: Hoàn toàn đồng ý vì trước đây 7 bậc là quá nhiều, khó để tính toán. | AE3: 3 | AF3: 5 | AG3: 2 | AH3: Chưa thấy nhiều thay đổi về các chế tài pháp lý hay xử phạt, chỉ giảm bậc thuế. | AI3: Các thay đổi hiện tại chỉ mới dừng lại ở việc giảm bậc thuế, giúp người đóng thuế cảm thấy đơn giản và nhẹ gánh trong việc đóng thuế TNCN. Chưa thấy nhiều thay đổi về các chế tài pháp lý hay xử phạt. | AJ3: 9 | AK3: 10 | AL3: 1 | AM3: Mức thuế mới theo chính sách giúp tôi không phải đóng thuế nữa nên cảm giác công bằng hơn. | AN3: Vì theo chính sách mới, tôi không phải đóng thuế nữa. Hoàn toàn đồng ý. | AO3: 4 | AP3: 5 | AQ3: 1 | AR3: Thuế giảm giúp cải thiện dịch vụ công, nhưng thực tế chưa rõ ràng về sử dụng hiệu quả. | AS3: Khi nào các chính sách chế tài được xử lý nghiêm, giải quyết vấn đề tham nhũng thì lòng tin của tôi sẽ cao hơn. | AT3: 9 | AU3: 10 | AV3: 1 | AW3: Chính phủ đã giải thích minh bạch về lý do và mục tiêu của việc sửa đổi thuế lần này. | AX3: Hoàn toàn đồng ý về việc truyền thông và giải thích của Chính phủ. | AY3: 7 | AZ3: 9 | BA3: 2 | BB3: Đây là cải cách tốt, giảm gánh nặng thuế cho người dân nhưng niềm tin thực thi còn thấp. | BC3: Ủng hộ việc giảm bậc, tăng mức giảm trừ gia cảnh nhưng niềm tin về việc thực thi chính sách thì không cao cho đến khi việc thực thi các chế tài là rõ ràng, minh bạch, nghiêm khắc. Nhìn chung, vì chính sách mới giúp tôi không phải đóng thuế nữa nên mức độ ủng hộ cao.
A4: 1 | B4: 3 | C4: 45 | D4: Nữ | E4: 30 - 39 | F4: Thành thị | G4: Sau Đại học | H4: Chính thức | I4: 27.5 | J4: 1 | K4: 6 | L4: 5 | M4: -1 | N4: Chưa thấy nhiều thay đổi về các chế tài pháp lý hay xử phạt, cơ quan thuế cần tăng cường thực thi. | O4: Các thay đổi hiện tại chỉ mới dừng lại ở việc giảm bậc thuế, giúp người đóng thuế cảm thấy đơn giản và nhẹ gánh trong việc đóng thuế TNCN. Chưa thấy nhiều thay đổi về các chế tài pháp lý hay xử phạt. | P4: 7 | Q4: 5 | R4: -2 | S4: Cơ quan thuế có khả năng và công nghệ để phát hiện trốn thuế nhưng phụ thuộc vào việc thực thi | T4: Đồng ý. Quan trọng là cơ quan thuế có muốn thực thi hay không. | U4: 3 | V4: 1 | W4: -2 | X4: Form khai báo/phản ánh không đồng bộ, thông tin liên hệ không đầy đủ | Y4: Form khai báo/phản ánh không đồng bộ, thông tin liên hệ không có, không có người tiếp nhận, hỗ trợ. Phần mềm eTax cũng không có phản hồi người nộp thuế. Người khai báo thuế gặp vấn đề bị người khác sử dụng CCCD để đăng ký mã số thuế tại 1 DN không làm việc mà cơ quan thuế không biết/không xử lý dù đã phản ánh nhiều lần. | Z4: 4 | AA4: 10 | AB4: 6 | AC4: Biểu thuế đơn giản hơn nhưng quá trình khai báo thuế vẫn còn gặp nhiều vấn đề | AD4: Hoàn toàn đồng ý vì trước đây 7 bậc là quá nhiều, khó để tính toán. | AE4: 5 | AF4: 5 | AG4: 0 | AH4: Chưa thấy nhiều thay đổi về các chế tài pháp lý hay xử phạt, cần minh bạch hơn trong thực thi chính sách | AI4: Các thay đổi hiện tại chỉ mới dừng lại ở việc giảm bậc thuế, giúp người đóng thuế cảm thấy đơn giản và nhẹ gánh trong việc đóng thuế TNCN. Chưa thấy nhiều thay đổi về các chế tài pháp lý hay xử phạt. | AJ4: 6 | AK4: 10 | AL4: 4 | AM4: Mức thuế mới giảm nên tôi cảm thấy công bằng nhưng vẫn lo ngại về việc thực thi | AN4: Vì theo chính sách mới, tôi không phải đóng thuế nữa. Hoàn toàn đồng ý. | AO4: 7 | AP4: 5 | AQ4: -2 | AR4: Thuế giảm nên tin rằng tiền đóng sẽ được sử dụng hiệu quả để cải thiện dịch vụ công | AS4: Khi nào các chính sách chế tài được xử lý nghiêm, giải quyết vấn đề tham nhũng thì lòng tin của tôi sẽ cao hơn. | AT4: 8 | AU4: 10 | AV4: 2 | AW4: Chính phủ đã giải thích rõ ràng về mục tiêu của việc sửa đổi thuế lần này | AX4: Hoàn toàn đồng ý về việc truyền thông và giải thích của Chính phủ. | AY4: 9 | AZ4: 9 | BA4: 0 | BB4: Mức độ ủng hộ cao vì giảm thuế nhưng vẫn lo ngại về thực thi các chế tài pháp lý | BC4: Ủng hộ việc giảm bậc, tăng mức giảm trừ gia cảnh nhưng niềm tin về việc thực thi chính sách thì không cao cho đến khi việc thực thi các chế tài là rõ ràng, minh bạch, nghiêm khắc. Nhìn chung, vì chính sách mới giúp tôi không phải đóng thuế nữa nên mức độ ủng hộ cao.
A5: 1 | B5: 4 | C5: 46 | D5: Nữ | E5: 30 - 39 | F5: Thành thị | G5: Sau Đại học | H5: Chính thức | I5: 27.5 | J5: 1 | K5: 4 | L5: 5 | M5: 1 | N5: Chưa thấy nhiều thay đổi về các chế tài pháp lý hay xử phạt. Chỉ cải cách giảm bậc thuế. | O5: Các thay đổi hiện tại chỉ mới dừng lại ở việc giảm bậc thuế, giúp người đóng thuế cảm thấy đơn giản và nhẹ gánh trong việc đóng thuế TNCN. Chưa thấy nhiều thay đổi về các chế tài pháp lý hay xử phạt. | P5: 6 | Q5: 5 | R5: -1 | S5: Cơ quan thuế có đủ khả năng và công nghệ để phát hiện trốn thuế nhưng thực tế chưa rõ ràng. | T5: Đồng ý. Quan trọng là cơ quan thuế có muốn thực thi hay không. | U5: 3 | V5: 1 | W5: -2 | X5: Form khai báo/phản ánh không đồng bộ, thông tin liên hệ không có, phần mềm eTax không phản hồi người nộp thuế. Trước đây 7 bậc là quá nhiều, khó để tính toán. | Y5: Form khai báo/phản ánh không đồng bộ, thông tin liên hệ không có, không có người tiếp nhận, hỗ trợ. Phần mềm eTax cũng không có phản hồi người nộp thuế. Người khai báo thuế gặp vấn đề bị người khác sử dụng CCCD để đăng ký mã số thuế tại 1 DN không làm việc mà cơ quan thuế không biết/không xử lý dù đã phản ánh nhiều lần. | Z5: 8 | AA5: 10 | AB5: 2 | AC5: Bậc thuế mới đơn giản, dễ hiểu và thực hiện hơn so với trước | AD5: Hoàn toàn đồng ý vì trước đây 7 bậc là quá nhiều, khó để tính toán. | AE5: 4 | AF5: 5 | AG5: 1 | AH5: Các thay đổi chỉ mới dừng lại ở việc giảm bậc thuế. Chưa thấy nhiều thay đổi về các chế tài pháp lý hay xử phạt. | AI5: Các thay đổi hiện tại chỉ mới dừng lại ở việc giảm bậc thuế, giúp người đóng thuế cảm thấy đơn giản và nhẹ gánh trong việc đóng thuế TNCN. Chưa thấy nhiều thay đổi về các chế tài pháp lý hay xử phạt. | AJ5: 9 | AK5: 10 | AL5: 1 | AM5: Mức thuế mới là công bằng và hợp lý cho thu nhập của tôi | AN5: Vì theo chính sách mới, tôi không phải đóng thuế nữa. Hoàn toàn đồng ý. | AO5: 7 | AP5: 5 | AQ5: -2 | AR5: Thuế đóng sẽ được sử dụng hiệu quả để cải thiện dịch vụ công nhưng lòng tin chưa cao do không rõ ràng về việc thực thi | AS5: Khi nào các chính sách chế tài được xử lý nghiêm, giải quyết vấn đề tham nhũng thì lòng tin của tôi sẽ cao hơn. | AT5: 8 | AU5: 10 | AV5: 2 | AW5: Chính phủ đã giải thích rõ ràng, minh bạch về lý do và mục tiêu của việc sửa đổi thuế lần này. Tuy nhiên, lòng tin vào việc thực hiện vẫn còn thấp | AX5: Hoàn toàn đồng ý về việc truyền thông và giải thích của Chính phủ. | AY5: 9 | AZ5: 9 | BA5: 0 | BB5: Cải cách thuế giúp tôi không phải đóng thuế nữa nên ủng hộ cao nhưng chưa hoàn toàn tin tưởng vào việc thực thi chính sách mới | BC5: Ủng hộ việc giảm bậc, tăng mức giảm trừ gia cảnh nhưng niềm tin về việc thực thi chính sách thì không cao cho đến khi việc thực thi các chế tài là rõ ràng, minh bạch, nghiêm khắc. Nhìn chung, vì chính sách mới giúp tôi không phải đóng thuế nữa nên mức độ ủng hộ cao.
A6: 1 | B6: 5 | C6: 47 | D6: Nữ | E6: 30 - 39 | F6: Thành thị | G6: Sau Đại học | H6: Chính thức | I6: 27.5 | J6: 1 | K6: 7 | L6: 5 | M6: -2 | N6: Công nghệ và hệ thống eTax đã cải thiện đáng kể nhưng vẫn còn hạn chế trong việc phát hiện gian lận. | O6: Các thay đổi hiện tại chỉ mới dừng lại ở việc giảm bậc thuế, giúp người đóng thuế cảm thấy đơn giản và nhẹ gánh trong việc đóng thuế TNCN. Chưa thấy nhiều thay đổi về các chế tài pháp lý hay xử phạt. | P6: 6 | Q6: 5 | R6: -1 | S6: Khả năng phát hiện và xử lý trốn thuế phụ thuộc vào sự nghiêm túc của cơ quan chức năng, chưa có thông tin rõ ràng về hiệu quả thực thi. | T6: Đồng ý. Quan trọng là cơ quan thuế có muốn thực thi hay không. | U6: 7 | V6: 1 | W6: -6 | X6: Thủ tục khai báo thuế đơn giản hơn nhưng vẫn gặp khó khăn về tính đồng bộ và hỗ trợ khách hàng. | Y6: Form khai báo/phản ánh không đồng bộ, thông tin liên hệ không có, không có người tiếp nhận, hỗ trợ. Phần mềm eTax cũng không có phản hồi người nộp thuế. Người khai báo thuế gặp vấn đề bị người khác sử dụng CCCD để đăng ký mã số thuế tại 1 DN không làm việc mà cơ quan thuế không biết/không xử lý dù đã phản ánh nhiều lần. | Z6: 9 | AA6: 10 | AB6: 1 | AC6: Bậc thuế mới đơn giản, dễ hiểu và thực hiện thuận lợi hơn so với trước đây. | AD6: Hoàn toàn đồng ý vì trước đây 7 bậc là quá nhiều, khó để tính toán. | AE6: 8 | AF6: 5 | AG6: -3 | AH6: Tôi tin rằng cơ quan thuế sẽ xử lý công bằng nhưng lo ngại về sự thực thi các chế tài pháp lý chưa rõ ràng. | AI6: Các thay đổi hiện tại chỉ mới dừng lại ở việc giảm bậc thuế, giúp người đóng thuế cảm thấy đơn giản và nhẹ gánh trong việc đóng thuế TNCN. Chưa thấy nhiều thay đổi về các chế tài pháp lý hay xử phạt. | AJ6: 9 | AK6: 10 | AL6: 1 | AM6: Mức thuế mới giảm đáng kể, cảm thấy công bằng và hợp lý với thu nhập hiện tại của tôi. | AN6: Vì theo chính sách mới, tôi không phải đóng thuế nữa. Hoàn toàn đồng ý. | AO6: 6 | AP6: 5 | AQ6: -1 | AR6: Hiện tôi không hoàn toàn tin rằng số tiền thuế đóng được sử dụng hiệu quả cho dịch vụ công | AS6: Khi nào các chính sách chế tài được xử lý nghiêm, giải quyết vấn đề tham nhũng thì lòng tin của tôi sẽ cao hơn. | AT6: 8 | AU6: 10 | AV6: 2 | AW6: Chính phủ đã giải thích rõ ràng về mục tiêu của chính sách mới nhưng cần minh bạch hơn trong thực thi. | AX6: Hoàn toàn đồng ý về việc truyền thông và giải thích của Chính phủ. | AY6: 7 | AZ6: 9 | BA6: 2 | BB6: Dù thuế giảm đáng kể, tôi vẫn lo ngại về vấn đề tham nhũng và hiệu quả sử dụng số tiền đóng thuế | BC6: Ủng hộ việc giảm bậc, tăng mức giảm trừ gia cảnh nhưng niềm tin về việc thực thi chính sách thì không cao cho đến khi việc thực thi các chế tài là rõ ràng, minh bạch, nghiêm khắc. Nhìn chung, vì chính sách mới giúp tôi không phải đóng thuế nữa nên mức độ ủng hộ cao.
A7: 2 | B7: 1 | C7: 2143 | D7: Nữ | E7: 30 - 39 | F7: Thành thị | G7: Đại học | H7: Phi chính thức | I7: 15 | J7: 2 | K7: 6 | L7: 5 | M7: -1 | N7: Dù khâu thực thi được chú trọng và nhiều cải thiện, nhưng thay đổi chỉ mới gần đây nên chưa chắc hiệu quả trong tương lai. | O7: Dù khâu thực thi được chú trọng và nhiều cải thiện. Người dân hiểu và tuân thủ hơn. Nhưng thay đổi chỉ mới gần đây, chưa chắc được hiệu quả trong tương lai. | P7: 6 | Q7: 5 | R7: -1 | S7: Dù khâu thực thi được chú trọng và nhiều cải thiện, nhưng thay đổi chỉ mới gần đây nên chưa chắc hiệu quả trong tương lai. | T7: Dù khâu thực thi được chú trọng và nhiều cải thiện. Người dân hiểu và tuân thủ hơn. Nhưng thay đổi chỉ mới gần đây, chưa chắc được hiệu quả trong tương lai. | U7: 8 | V7: 4 | W7: -4 | X7: Sau khi giảm bớt mức độ phức tạp, quy trình làm việc với cơ quan thuế đã đơn giản hơn và tiện lợi hơn so với trước đây. | Y7: Có cải thiện nhưng đang trong quá trình chuyển giao, thay đổi từ offline sang online nên mọi thứ vẫn còn ngổn ngang, không biết liên hệ ai. | Z7: 7 | AA7: 5 | AB7: -2 | AC7: Biểu thuế mới có ít bậc hơn nên dễ hiểu và thực hiện hơn. Tuy nhiên, vẫn còn ngổn ngang khi chuyển giao từ offline sang online. | AD7: Không thay đổi về mức độ đóng thuế dù thay đổi bậc thuế, ngưỡng thuế. | AE7: 9 | AF7: 5 | AG7: -4 | AH7: Tôi tin rằng Nhà nước sẽ thực thi chính sách một cách khách quan, công tâm và đối xử bình đẳng với mọi người nộp thuế, mặc dù thay đổi mới chỉ vừa được áp dụng. | AI7: Dù khâu thực thi được chú trọng và nhiều cải thiện. Người dân hiểu và tuân thủ hơn. Nhưng thay đổi chỉ mới gần đây, chưa chắc được hiệu quả trong tương lai. | AJ7: 8 | AK7: 5 | AL7: -3 | AM7: Nhìn chung mức thuế tôi phải đóng theo phương án mới là hợp lý. Mức giảm trừ gia cảnh cao hơn giúp giảm gánh nặng tài chính cho người dân. | AN7: Không thay đổi về mức độ đóng thuế dù thay đổi bậc thuế, ngưỡng thuế. | AO7: 7 | AP7: 5 | AQ7: -2 | AR7: Tôi tin tưởng số tiền thuế tôi đóng sẽ được Nhà nước sử dụng hiệu quả để cải thiện dịch vụ công, mặc dù chưa rõ ràng về chi tiết cụ thể. | AS7: Giống với quan điểm trước đó vì mọi thứ vẫn chưa rõ ràng. | AT7: 8 | AU7: 5 | AV7: -3 | AW7: Nhà nước đã giải thích rõ ràng về mục tiêu của việc sửa đổi thuế lần này. Mặc dù thay đổi mới chỉ vừa được áp dụng, nhưng tôi thấy có sự minh bạch hơn. | AX7: Giống với quan điểm trước đó vì mọi thứ vẫn chưa rõ ràng. | AY7: 9 | AZ7: 5 | BA7: -4 | BB7: Dù vẫn còn nhiều vấn đề cần cải thiện, nhưng chính sách mới đã giúp giảm gánh nặng thuế cho người dân và làm đơn giản hóa quy trình khai báo thuế. Tôi ủng hộ và tuân thủ chính sách này. | BC7: Giống với quan điểm trước đó vì mọi thứ vẫn chưa rõ ràng.
A8: 2 | B8: 2 | C8: 144 | D8: Nữ | E8: 30 - 39 | F8: Thành thị | G8: Đại học | H8: Phi chính thức | I8: 15 | J8: 2 | K8: 6 | L8: 5 | M8: -1 | N8: Dù khâu thực thi được chú trọng và nhiều cải thiện, nhưng thay đổi chỉ mới gần đây, chưa chắc được hiệu quả trong tương lai. | O8: Dù khâu thực thi được chú trọng và nhiều cải thiện. Người dân hiểu và tuân thủ hơn. Nhưng thay đổi chỉ mới gần đây, chưa chắc được hiệu quả trong tương lai. | P8: 6 | Q8: 5 | R8: -1 | S8: Dù khâu thực thi được chú trọng và nhiều cải thiện, nhưng thay đổi chỉ mới gần đây, chưa chắc được hiệu quả trong tương lai. | T8: Dù khâu thực thi được chú trọng và nhiều cải thiện. Người dân hiểu và tuân thủ hơn. Nhưng thay đổi chỉ mới gần đây, chưa chắc được hiệu quả trong tương lai. | U8: 5 | V8: 4 | W8: -1 | X8: Có cải thiện nhưng đang trong quá trình chuyển giao, thay đổi từ offline sang online nên mọi thứ vẫn còn ngổn ngang, không biết liên hệ ai. | Y8: Có cải thiện nhưng đang trong quá trình chuyển giao, thay đổi từ offline sang online nên mọi thứ vẫn còn ngổn ngang, không biết liên hệ ai. | Z8: 7 | AA8: 5 | AB8: -2 | AC8: So với trước đây, cách tính thuế và các bậc thuế trong phương án mới đơn giản, dễ hiểu và dễ thực hiện hơn. Tuy nhiên, do chưa quen thuộc nên điểm số không cao. | AD8: Không thay đổi về mức độ đóng thuế dù thay đổi bậc thuế, ngưỡng thuế. | AE8: 6 | AF8: 5 | AG8: -1 | AH8: Dù khâu thực thi được chú trọng và nhiều cải thiện. Người dân hiểu và tuân thủ hơn. Nhưng thay đổi chỉ mới gần đây, chưa chắc được hiệu quả trong tương lai. | AI8: Dù khâu thực thi được chú trọng và nhiều cải thiện. Người dân hiểu và tuân thủ hơn. Nhưng thay đổi chỉ mới gần đây, chưa chắc được hiệu quả trong tương lai. | AJ8: 8 | AK8: 5 | AL8: -3 | AM8: Mức thuế tôi phải đóng theo phương án mới là công bằng (người thu nhập như tôi đóng mức này là hợp lý). | AN8: Không thay đổi về mức độ đóng thuế dù thay đổi bậc thuế, ngưỡng thuế. | AO8: 5 | AP8: 5 | AQ8: 0 | AR8: Giống với quan điểm trước đó vì mọi thứ vẫn chưa rõ ràng. | AS8: Giống với quan điểm trước đó vì mọi thứ vẫn chưa rõ ràng. | AT8: 5 | AU8: 5 | AV8: 0 | AW8: Giống với quan điểm trước đó vì mọi thứ vẫn chưa rõ ràng. | AX8: Giống với quan điểm trước đó vì mọi thứ vẫn chưa rõ ràng. | AY8: 7 | AZ8: 5 | BA8: -2 | BB8: Sau khi xem xét các quyền lợi và nghĩa vụ, tôi ủng hộ và tuân thủ chính sách mới hiện nay. Đây là bước tiến tốt nhưng cần thời gian để thích ứng. | BC8: Giống với quan điểm trước đó vì mọi thứ vẫn chưa rõ ràng.
A9: 2 | B9: 3 | C9: 145 | D9: Nữ | E9: 30 - 39 | F9: Thành thị | G9: Đại học | H9: Phi chính thức | I9: 15 | J9: 2 | K9: 6 | L9: 5 | M9: -1 | N9: Dù khâu thực thi được chú trọng và nhiều cải thiện, nhưng thay đổi chỉ mới gần đây nên chưa chắc hiệu quả trong tương lai. | O9: Dù khâu thực thi được chú trọng và nhiều cải thiện. Người dân hiểu và tuân thủ hơn. Nhưng thay đổi chỉ mới gần đây, chưa chắc được hiệu quả trong tương lai. | P9: 6 | Q9: 5 | R9: -1 | S9: Dù khâu thực thi được chú trọng và nhiều cải thiện, nhưng thay đổi chỉ mới gần đây nên chưa chắc hiệu quả trong tương lai. | T9: Dù khâu thực thi được chú trọng và nhiều cải thiện. Người dân hiểu và tuân thủ hơn. Nhưng thay đổi chỉ mới gần đây, chưa chắc được hiệu quả trong tương lai. | U9: 4 | V9: 4 | W9: 0 | X9: Có cải thiện nhưng đang trong quá trình chuyển giao, thay đổi từ offline sang online nên mọi thứ vẫn còn ngổn ngang, không biết liên hệ ai. | Y9: Có cải thiện nhưng đang trong quá trình chuyển giao, thay đổi từ offline sang online nên mọi thứ vẫn còn ngổn ngang, không biết liên hệ ai. | Z9: 7 | AA9: 5 | AB9: -2 | AC9: So với trước đây, cách tính thuế và các bậc thuế trong phương án mới đơn giản, dễ hiểu và dễ thực hiện hơn nhưng chưa rõ ràng hết. | AD9: Không thay đổi về mức độ đóng thuế dù thay đổi bậc thuế, ngưỡng thuế. | AE9: 5 | AF9: 5 | AG9: 0 | AH9: Dù khâu thực thi được chú trọng và nhiều cải thiện. Người dân hiểu và tuân thủ hơn. Nhưng thay đổi chỉ mới gần đây, chưa chắc được hiệu quả trong tương lai. | AI9: Dù khâu thực thi được chú trọng và nhiều cải thiện. Người dân hiểu và tuân thủ hơn. Nhưng thay đổi chỉ mới gần đây, chưa chắc được hiệu quả trong tương lai. | AJ9: 8 | AK9: 5 | AL9: -3 | AM9: Mức thuế tôi phải đóng theo phương án mới là công bằng (người thu nhập như tôi đóng mức này là hợp lý) nhưng còn cần thời gian để quen thuộc. | AN9: Không thay đổi về mức độ đóng thuế dù thay đổi bậc thuế, ngưỡng thuế. | AO9: 9 | AP9: 5 | AQ9: -4 | AR9: Tôi tin tưởng số tiền thuế tôi đóng sẽ được Nhà nước sử dụng hiệu quả để cải thiện dịch vụ công (y tế, đường xá...). | AS9: Giống với quan điểm trước đó vì mọi thứ vẫn chưa rõ ràng. | AT9: 10 | AU9: 5 | AV9: -5 | AW9: Nhà nước đã giải thích rõ ràng, minh bạch về lý do và mục tiêu của việc sửa đổi thuế lần này. | AX9: Giống với quan điểm trước đó vì mọi thứ vẫn chưa rõ ràng. | AY9: 9 | AZ9: 5 | BA9: -4 | BB9: Sau khi xem xét các quyền lợi và nghĩa vụ, tôi ủng hộ và tuân thủ chính sách mới hiện nay vì mức giảm trừ gia cảnh cao hơn thu nhập của tôi. | BC9: Giống với quan điểm trước đó vì mọi thứ vẫn chưa rõ ràng.
A10: 2 | B10: 4 | C10: 146 | D10: Nữ | E10: 30 - 39 | F10: Thành thị | G10: Đại học | H10: Phi chính thức | I10: 15 | J10: 2 | K10: 6 | L10: 5 | M10: -1 | N10: Dù khâu thực thi được chú trọng và nhiều cải thiện, nhưng thay đổi chỉ mới gần đây nên chưa chắc chắn về hiệu quả trong tương lai. | O10: Dù khâu thực thi được chú trọng và nhiều cải thiện. Người dân hiểu và tuân thủ hơn. Nhưng thay đổi chỉ mới gần đây, chưa chắc được hiệu quả trong tương lai. | P10: 6 | Q10: 5 | R10: -1 | S10: Dù khâu thực thi được chú trọng và nhiều cải thiện, nhưng thay đổi chỉ mới gần đây nên chưa chắc chắn về hiệu quả trong tương lai. | T10: Dù khâu thực thi được chú trọng và nhiều cải thiện. Người dân hiểu và tuân thủ hơn. Nhưng thay đổi chỉ mới gần đây, chưa chắc được hiệu quả trong tương lai. | U10: 7 | V10: 4 | W10: -3 | X10: Cách tính thuế và các bậc thuế đơn giản hơn so với trước đây, nhưng quy trình làm việc với cơ quan thuế vẫn còn ngổn ngang. | Y10: Có cải thiện nhưng đang trong quá trình chuyển giao, thay đổi từ offline sang online nên mọi thứ vẫn còn ngổn ngang, không biết liên hệ ai. | Z10: 8 | AA10: 5 | AB10: -3 | AC10: Số bậc thuế giảm đi, thủ tục khai báo thuế cũng đơn giản và dễ hiểu hơn | AD10: Không thay đổi về mức độ đóng thuế dù thay đổi bậc thuế, ngưỡng thuế. | AE10: 9 | AF10: 5 | AG10: -4 | AH10: Tôi tin rằng Nhà nước, cơ quan thuế sẽ thực thi chính sách mới một cách khách quan, công tâm và đối xử bình đẳng với mọi người nộp thuế. | AI10: Dù khâu thực thi được chú trọng và nhiều cải thiện. Người dân hiểu và tuân thủ hơn. Nhưng thay đổi chỉ mới gần đây, chưa chắc được hiệu quả trong tương lai. | AJ10: 8 | AK10: 5 | AL10: -3 | AM10: Mức giảm trừ gia cảnh cao hơn thu nhập nên tôi không phải đóng thuế. Đây là mức thuế hợp lý cho thu nhập của tôi | AN10: Không thay đổi về mức độ đóng thuế dù thay đổi bậc thuế, ngưỡng thuế. | AO10: 9 | AP10: 5 | AQ10: -4 | AR10: Tôi tin tưởng số tiền thuế tôi đóng sẽ được Nhà nước sử dụng hiệu quả để cải thiện dịch vụ công (y tế, đường xá...). | AS10: Giống với quan điểm trước đó vì mọi thứ vẫn chưa rõ ràng. | AT10: 8 | AU10: 5 | AV10: -3 | AW10: Nhà nước đã giải thích rõ ràng về lý do và mục tiêu của việc sửa đổi thuế lần này. | AX10: Giống với quan điểm trước đó vì mọi thứ vẫn chưa rõ ràng. | AY10: 7 | AZ10: 5 | BA10: -2 | BB10: Dù các thay đổi mang lại nhiều lợi ích cho tôi nhưng chưa chắc chắn về hiệu quả thực thi trong tương lai nên vẫn còn nghi ngờ | BC10: Giống với quan điểm trước đó vì mọi thứ vẫn chưa rõ ràng.
A11: 2 | B11: 5 | C11: 147 | D11: Nữ | E11: 30 - 39 | F11: Thành thị | G11: Đại học | H11: Phi chính thức | I11: 15 | J11: 2 | K11: 6 | L11: 5 | M11: -1 | N11: Dù khâu thực thi được chú trọng và nhiều cải thiện nhưng thay đổi chỉ mới gần đây, chưa chắc được hiệu quả trong tương lai. | O11: Dù khâu thực thi được chú trọng và nhiều cải thiện. Người dân hiểu và tuân thủ hơn. Nhưng thay đổi chỉ mới gần đây, chưa chắc được hiệu quả trong tương lai. | P11: 6 | Q11: 5 | R11: -1 | S11: Dù khâu thực thi được chú trọng và nhiều cải thiện nhưng thay đổi chỉ mới gần đây, chưa chắc được hiệu quả trong tương lai. | T11: Dù khâu thực thi được chú trọng và nhiều cải thiện. Người dân hiểu và tuân thủ hơn. Nhưng thay đổi chỉ mới gần đây, chưa chắc được hiệu quả trong tương lai. | U11: 4 | V11: 4 | W11: 0 | X11: Có cải thiện nhưng đang trong quá trình chuyển giao, thay đổi từ offline sang online nên mọi thứ vẫn còn ngổn ngang, không biết liên hệ ai. | Y11: Có cải thiện nhưng đang trong quá trình chuyển giao, thay đổi từ offline sang online nên mọi thứ vẫn còn ngổn ngang, không biết liên hệ ai. | Z11: 8 | AA11: 5 | AB11: -3 | AC11: So với trước đây, tôi thấy cách tính thuế và các bậc thuế trong phương án mới đơn giản, dễ hiểu và dễ thực hiện hơn. | AD11: Không thay đổi về mức độ đóng thuế dù thay đổi bậc thuế, ngưỡng thuế. | AE11: 5 | AF11: 5 | AG11: 0 | AH11: Dù khâu thực thi được chú trọng và nhiều cải thiện. Người dân hiểu và tuân thủ hơn. Nhưng thay đổi chỉ mới gần đây, chưa chắc được hiệu quả trong tương lai. | AI11: Dù khâu thực thi được chú trọng và nhiều cải thiện. Người dân hiểu và tuân thủ hơn. Nhưng thay đổi chỉ mới gần đây, chưa chắc được hiệu quả trong tương lai. | AJ11: 9 | AK11: 5 | AL11: -4 | AM11: Tôi thấy mức thuế tôi phải đóng theo phương án mới là công bằng (người thu nhập như tôi đóng mức này là hợp lý). | AN11: Không thay đổi về mức độ đóng thuế dù thay đổi bậc thuế, ngưỡng thuế. | AO11: 4 | AP11: 5 | AQ11: 1 | AR11: Giống với quan điểm trước đó vì mọi thứ vẫn chưa rõ ràng. | AS11: Giống với quan điểm trước đó vì mọi thứ vẫn chưa rõ ràng. | AT11: 7 | AU11: 5 | AV11: -2 | AW11: Tôi thấy Nhà nước đã giải thích rõ ràng, minh bạch về lý do và mục tiêu của việc sửa đổi thuế lần này. | AX11: Giống với quan điểm trước đó vì mọi thứ vẫn chưa rõ ràng. | AY11: 5 | AZ11: 5 | BA11: 0 | BB11: Giống với quan điểm trước đó vì mọi thứ vẫn chưa rõ ràng nhưng tôi tin rằng với mức giảm trừ gia cảnh cao hơn, mình không cần phải đóng thuế nữa. | BC11: Giống với quan điểm trước đó vì mọi thứ vẫn chưa rõ ràng.
A12: 3 | B12: 1 | C12: 243 | D12: Nam | E12: 40 - 49 | F12: Thành thị | G12: Đại học | H12: Phi chính thức | I12: 27.5 | J12: 3 | K12: 6 | L12: 10 | M12: 4 | N12: Dù công nghệ hiện đại giúp phát hiện gian lận, nhưng tôi vẫn lo ngại về khả năng thực thi và sự công bằng trong quá trình xử lý. | O12: Áp dụng công nghệ định danh, rà soát tài khoản tự động các nguồn thu thông qua yêu cầu bên trung gian thanh toán, phán đoán cá nhân. | P12: 8 | Q12: 10 | R12: 2 | S12: Tôi tin rằng cơ quan thuế có đủ nguồn lực để quản lý thuế hiệu quả hơn nhờ các cải cách này. | T12: Công nghệ hiện đại | U12: 5 | V12: 5 | W12: 0 | X12: Các quy trình khai báo đã đơn giản hơn, nhưng tôi vẫn cảm thấy chưa thật sự thuận tiện do chưa quen với hệ thống mới. | Y12: Vẫn thấy có nhiều khó khăn khi dùng Etax mobile. Chưa rõ phần mềm có cập nhật, thay đổi theo chính sách mới hay không. | Z12: 8 | AA12: 7 | AB12: -1 | AC12: Biểu thuế đơn giản hơn, dễ hiểu và thực hiện dễ dàng hơn so với trước đây. | AD12: Chưa làm theo quy định mới nhưng từ truyền thông giải thích thì cảm giác có sự tốt hơn | AE12: 6 | AF12: 7 | AG12: 1 | AH12: Tôi hy vọng rằng sự công bằng sẽ được duy trì trong quá trình áp dụng chính sách mới, nhưng vẫn có hoài nghi về thực tế. | AI12: Vì còn mới và chưa triển khai, nên phỏng đoán sẽ tốt hơn cách làm trước đây. Dựa trên kinh nghiệm từ quá khứ thì mọi thứ vẫn làm tốt, nhưng chưa chắc tương lai thế nào vì không biết quá trình chuyển đổi thế nào. | AJ12: 7 | AK12: 6 | AL12: -1 | AM12: Đối với thu nhập của tôi, mức thuế mới này là hợp lý và công bằng. | AN12: Do sức mua bị giảm bởi lạm phát do cung tiền cho các dự án quốc gia, nên cảm thấy 6/10. Thay đổi chưa phù hợp với mức sống thực tế. | AO12: 6 | AP12: 5 | AQ12: -1 | AR12: Tôi tin rằng tiền thuế đóng góp sẽ được sử dụng hiệu quả để cải thiện các dịch vụ công, nhưng vẫn lo ngại về minh bạch trong quá trình sử dụng. | AS12: Tính hiệu quả từ tiền thuế thu được chưa được minh bạch và giải trình đầy đủ, còn nhiều vụ án tham nhũng khi triển khai dự án công, trong đó có phần tiền thuế đóng góp. | AT12: 5 | AU12: 6 | AV12: 1 | AW12: Những giải thích về chính sách mới chưa đủ chi tiết và rõ ràng như tôi mong đợi, nhưng tôi hy vọng rằng sự minh bạch sẽ được cải thiện. | AX12: Chỉ tham khảo từ nguồn truyền thông. Chưa thấy thông tin từ cơ quan thuế, giới học thuật (sách vở). | AY12: 7 | AZ12: 7 | BA12: 0 | BB12: Thuế giảm đi đáng kể, cộng với mức thuế đơn giản hơn, đã làm tăng niềm tin của tôi về chính sách mới. Tuy nhiên, vẫn có một số lo ngại cần giải quyết. | BC12: Đóng thuế ít hơn, các khung thuế cũng đơn giản hơn. Nhưng tổng thể không đáp ứng được mong đợi so với thực mức sống thực tế. Tuy nhiên, sẽ ủng hộ nếu thu thuế tốt cho cả quốc gia nếu xài tiền thuế thu được hiệu quả.
A13: 3 | B13: 2 | C13: 244 | D13: Nam | E13: 40 - 49 | F13: Thành thị | G13: Đại học | H13: Phi chính thức | I13: 27.5 | J13: 3 | K13: 7 | L13: 10 | M13: 3 | N13: Hiện nay có nhiều công nghệ định danh và rà soát tự động, nhưng tôi vẫn lo ngại về khả năng phát hiện trốn thuế của cơ quan thuế. | O13: Áp dụng công nghệ định danh, rà soát tài khoản tự động các nguồn thu thông qua yêu cầu bên trung gian thanh toán, phán đoán cá nhân. | P13: 6 | Q13: 10 | R13: 4 | S13: Cơ quan thuế sử dụng công nghệ là điều tốt, nhưng tôi chưa chắc chắn liệu họ có đủ năng lực và nguồn lực thực hiện hiệu quả | T13: Công nghệ hiện đại | U13: 8 | V13: 5 | W13: -3 | X13: Mức độ thuận tiện đã tăng do số bậc thuế giảm và giảm trừ gia cảnh lớn hơn. Tuy nhiên, việc chuyển đổi từ hệ thống cũ sang mới có thể gây thêm khó khăn. | Y13: Vẫn thấy có nhiều khó khăn khi dùng Etax mobile. Chưa rõ phần mềm có cập nhật, thay đổi theo chính sách mới hay không. | Z13: 7 | AA13: 7 | AB13: 0 | AC13: Biểu thuế đơn giản hóa nhiều nhưng tôi vẫn thấy cần cải thiện thêm trong việc hướng dẫn và hỗ trợ người nộp thuế | AD13: Chưa làm theo quy định mới nhưng từ truyền thông giải thích thì cảm giác có sự tốt hơn | AE13: 5 | AF13: 7 | AG13: 2 | AH13: Tôi tin Nhà nước sẽ công tâm khi thực thi, nhưng không có thông tin cụ thể về quy trình mới nên còn nghi ngờ | AI13: Vì còn mới và chưa triển khai, nên phỏng đoán sẽ tốt hơn cách làm trước đây. Dựa trên kinh nghiệm từ quá khứ thì mọi thứ vẫn làm tốt, nhưng chưa chắc tương lai thế nào vì không biết quá trình chuyển đổi thế nào. | AJ13: 6 | AK13: 6 | AL13: 0 | AM13: Mức thuế mới giảm so với trước đây, nhưng tôi vẫn lo ngại về hiệu quả sử dụng nguồn thu | AN13: Do sức mua bị giảm bởi lạm phát do cung tiền cho các dự án quốc gia, nên cảm thấy 6/10. Thay đổi chưa phù hợp với mức sống thực tế. | AO13: 5 | AP13: 5 | AQ13: 0 | AR13: Tôi tin số tiền thuế đóng sẽ được sử dụng hiệu quả cho dịch vụ công, nhưng cần nhiều thông tin hơn về cách chi tiêu | AS13: Tính hiệu quả từ tiền thuế thu được chưa được minh bạch và giải trình đầy đủ, còn nhiều vụ án tham nhũng khi triển khai dự án công, trong đó có phần tiền thuế đóng góp. | AT13: 6 | AU13: 6 | AV13: 0 | AW13: Nhà nước đã giải thích rõ mục đích của việc sửa đổi, nhưng tôi vẫn mong muốn có thêm minh bạch trong quy trình thực thi | AX13: Chỉ tham khảo từ nguồn truyền thông. Chưa thấy thông tin từ cơ quan thuế, giới học thuật (sách vở). | AY13: 7 | AZ13: 7 | BA13: 0 | BB13: Sau khi tính toán tác động tài chính và thay đổi về biểu thuế, tôi thấy ủng hộ chính sách mới, mặc dù còn nhiều lo ngại. | BC13: Đóng thuế ít hơn, các khung thuế cũng đơn giản hơn. Nhưng tổng thể không đáp ứng được mong đợi so với thực mức sống thực tế. Tuy nhiên, sẽ ủng hộ nếu thu thuế tốt cho cả quốc gia nếu xài tiền thuế thu được hiệu quả.
... A126: 25 | B126: 5 | C126: 2447 | D126: Nữ | E126: 40 - 49 | F126: Thành thị | G126: Đại học | H126: Chính thức | I126: 15 | J126: 2 | K126: 9 | L126: 8 | M126: -1 | N126: Việc tăng giảm trừ gia cảnh và đơn giản hóa biểu thuế làm giảm khả năng trốn thuế, thêm vào đó công nghệ hiện đại giúp nhà nước quản lý hiệu quả. | O126: rõ ràng, minh bạch hơn | P126: 8 | Q126: 8 | R126: 0 | S126: Nhà nước có đủ nguồn lực và công nghệ để giám sát và xử lý các hành vi gian lận thuế một cách nhanh chóng và chính xác. | T126: quản lý cơ sở dữ liệu khoa học, hiện đại hơn | U126: 9 | V126: 8 | W126: -1 | X126: Thủ tục khai báo thuế đơn giản hơn, dễ thực hiện và ít rườm rà so với trước đây. | Y126: đã có thủ tục hành chính rõ ràng cụ thể, dịch vụ hành chính công | Z126: 8 | AA126: 8 | AB126: 0 | AC126: Bậc thuế mới rõ ràng và dễ hiểu hơn, giảm bớt sự phức tạp khi tính toán thuế. | AD126: có phương án tính rõ ràng | AE126: 9 | AF126: 8 | AG126: -1 | AH126: Nhà nước đã cải cách thuế một cách công bằng và khách quan, đảm bảo mọi người nộp thuế đều được đối xử bình đẳng. | AI126: vì chính sách, quy định, thủ tục minh bạch, rõ ràng, công khai | AJ126: 8 | AK126: 8 | AL126: 0 | AM126: Dựa trên mức giảm trừ gia cảnh cao hơn thu nhập của tôi, tôi thấy mức thuế mới là hợp lý. | AN126: người thu nhập như tôi đóng mức này là hợp lý | AO126: 9 | AP126: 9 | AQ126: 0 | AR126: Nhà nước đang sử dụng số tiền thuế này để cải thiện chất lượng các dịch vụ công và cơ sở hạ tầng. | AS126: Nhà nước đang sử dụng rất hiệu quả để cải thiện hàng hoá công và dịch vụ công | AT126: 8 | AU126: 8 | AV126: 0 | AW126: Các biện pháp cải cách thuế đã được giải thích rõ ràng trên các phương tiện truyền thông, thể hiện sự minh bạch của chính phủ. | AX126: giải thích rõ ràng, công khai trên các phương tiện truyền thông | AY126: 9 | AZ126: 10 | BA126: 1 | BB126: Tôi ủng hộ và tuân thủ chính sách mới vì nó công bằng hơn so với trước đây. | BC126: tôi ủng hộ và tuân thủ chính sách thuế của Nhà nước

Sheet interview_responses
A1: Timestamp | B1: Giới tính của bạn: | C1: Độ tuổi của bạn: | D1: Khu vực bạn đang sinh sống: | E1: Trình độ học vấn cao nhất: | F1: Tình trạng việc làm chính: | G1: Thu nhập bình quân tháng theo Hợp đồng lao động của bạn là bao nhiêu? (Vui lòng điền tổng thu nhập trước khi khấu trừ các loại Bảo hiểm (BHXH, BHYT, BHTN) và Thuế TNCN) | H1: Số người phụ thuộc (con nhỏ, cha mẹ già...) đủ điều kiện giảm trừ gia cảnh: | I1: Tôi tin rằng với các quy định quản lý thuế hiện nay, hành vi gian lận hoặc trốn thuế sẽ dễ dàng bị phát hiện và xử lý nghiêm. - HUMAN-ENF1 | J1: Lý do - HUMAN-ENF1 | K1: Tôi tin rằng Nhà nước, cơ quan thuế có đủ khả năng và công nghệ để phát hiện, xử lý nghiêm các hành vi trốn thuế. - HUMAN-ENF2 | L1: Lý do - HUMAN-ENF2 | M1: Các thủ tục khai báo thuế VÀ/HOẶC quy trình làm việc với cơ quan thuế đơn giản, tiện lợi, nhanh chóng hơn so với trước đây. - HUMAN-FAC1 | N1: Lý do - HUMAN-FAC1 | O1: So với trước đây, tôi thấy cách tính thuế và các bậc thuế trong phương án mới đơn giản, dễ hiểu và dễ thực hiện hơn. - HUMAN-FAC2 | P1: Lý do - HUMAN-FAC2 | Q1: Tôi tin rằng Nhà nước, cơ quan thuế sẽ thực thi chính sách mới một cách khách quan, công tâm và đối xử bình đẳng với mọi người nộp thuế. - HUMAN-TRU1 | R1: Lý do - HUMAN-TRU1 | S1: Tôi thấy mức thuế tôi phải đóng theo phương án mới là công bằng (người thu nhập như tôi đóng mức này là hợp lý). - HUMAN-TRU2 | T1: Lý do - HUMAN-TRU2 | U1: Tôi tin tưởng số tiền thuế tôi đóng sẽ được Nhà nước sử dụng hiệu quả để cải thiện dịch vụ công (y tế, đường xá...). - HUMAN-TRU3 | V1: Lý do - HUMAN-TRU3 | W1: Tôi thấy Nhà nước đã giải thích rõ ràng, minh bạch về lý do và mục tiêu của việc sửa đổi thuế lần này. - HUMAN-TRU4 | X1: Lý do - HUMAN-TRU4 | Y1: Sau khi xem xét các quyền lợi và nghĩa vụ, bạn có ủng hộ và tuân thủ chính sách mới hiện nay? - HUMAN-OUT1 | Z1: Lý do - HUMAN-OUT1 | AA1: Vui lòng phân bổ tổng cộng 100 điểm vào 3 yếu tố dưới đây (Tổng 3 ô phải bằng đúng 100): Tổng điểm = Thực thi + Thuận tiện + Niềm tin = 100 điểm Tính Thực thi (Enforcement): ............ điểm | AB1: Vui lòng phân bổ tổng cộng 100 điểm vào 3 yếu tố dưới đây (Tổng 3 ô phải bằng đúng 100): Tổng điểm = Thực thi + Thuận tiện + Niềm tin = 100 điểm Tính Thuận tiện (Facilitation): ............ điểm | AC1: Vui lòng phân bổ tổng cộng 100 điểm vào 3 yếu tố dưới đây (Tổng 3 ô phải bằng đúng 100): Tổng điểm = Thực thi + Thuận tiện + Niềm tin = 100 điểm Niềm tin (Trust): ............ điểm | AD1: Nghề nghiệp | AE1: Total
A2: 46014.849 | B2: Nữ | C2: 30 - 39 | D2: Thành thị | E2: Sau Đại học | F2: Khu vực chính thức (Có Hợp đồng lao động, đóng BHXH) | G2: Từ 23 - 32 triệu VNĐ | H2: 1 người | I2: 5 | J2: Các thay đổi hiện tại chỉ mới dừng lại ở việc giảm bậc thuế, giúp người đóng thuế cảm thấy đơn giản và nhẹ gánh trong việc đóng thuế TNCN. Chưa thấy nhiều thay đổi về các chế tài pháp lý hay xử phạt. | K2: 5 | L2: Đồng ý. Quan trọng là cơ quan thuế có muốn thực thi hay không. | M2: 1 | N2: Form khai báo/phản ánh không đồng bộ, thông tin liên hệ không có, không có người tiếp nhận, hỗ trợ. Phần mềm eTax cũng không có phản hồi người nộp thuế. Người khai báo thuế gặp vấn đề bị người khác sử dụng CCCD để đăng ký mã số thuế tại 1 DN không làm việc mà cơ quan thuế không biết/không xử lý dù đã phản ánh nhiều lần. | O2: 10 | P2: Hoàn toàn đồng ý vì trước đây 7 bậc là quá nhiều, khó để tính toán. | Q2: 5 | R2: Các thay đổi hiện tại chỉ mới dừng lại ở việc giảm bậc thuế, giúp người đóng thuế cảm thấy đơn giản và nhẹ gánh trong việc đóng thuế TNCN. Chưa thấy nhiều thay đổi về các chế tài pháp lý hay xử phạt. | S2: 10 | T2: Vì theo chính sách mới, tôi không phải đóng thuế nữa. Hoàn toàn đồng ý. | U2: 5 | V2: Khi nào các chính sách chế tài được xử lý nghiêm, giải quyết vấn đề tham nhũng thì lòng tin của tôi sẽ cao hơn. | W2: 10 | X2: Hoàn toàn đồng ý về việc truyền thông và giải thích của Chính phủ. | Y2: 9 | Z2: Ủng hộ việc giảm bậc, tăng mức giảm trừ gia cảnh nhưng niềm tin về việc thực thi chính sách thì không cao cho đến khi việc thực thi các chế tài là rõ ràng, minh bạch, nghiêm khắc. Nhìn chung, vì chính sách mới giúp tôi không phải đóng thuế nữa nên mức độ ủng hộ cao. | AA2: 35 | AB2: 40 | AC2: 25 | AD2: Nhân viên văn phòng - Chuyên viên bảo hiểm | AE2: =SUM(AA2:AC2) -> 100
A3: 46015.4 | B3: Nữ | C3: 30 - 39 | D3: Thành thị | E3: Đại học | F3: Khu vực phi chính thức (Lao động tự do, không có HĐLĐ) | G3: Từ 12 - 18 triệu VNĐ | H3: 2 người | I3: 5 | J3: Dù khâu thực thi được chú trọng và nhiều cải thiện. Người dân hiểu và tuân thủ hơn. Nhưng thay đổi chỉ mới gần đây, chưa chắc được hiệu quả trong tương lai. | K3: 5 | L3: Dù khâu thực thi được chú trọng và nhiều cải thiện. Người dân hiểu và tuân thủ hơn. Nhưng thay đổi chỉ mới gần đây, chưa chắc được hiệu quả trong tương lai. | M3: 4 | N3: Có cải thiện nhưng đang trong quá trình chuyển giao, thay đổi từ offline sang online nên mọi thứ vẫn còn ngổn ngang, không biết liên hệ ai. | O3: 5 | P3: Không thay đổi về mức độ đóng thuế dù thay đổi bậc thuế, ngưỡng thuế. | Q3: 5 | R3: Dù khâu thực thi được chú trọng và nhiều cải thiện. Người dân hiểu và tuân thủ hơn. Nhưng thay đổi chỉ mới gần đây, chưa chắc được hiệu quả trong tương lai. | S3: 5 | T3: Không thay đổi về mức độ đóng thuế dù thay đổi bậc thuế, ngưỡng thuế. | U3: 5 | V3: Giống với quan điểm trước đó vì mọi thứ vẫn chưa rõ ràng. | W3: 5 | X3: Giống với quan điểm trước đó vì mọi thứ vẫn chưa rõ ràng. | Y3: 5 | Z3: Giống với quan điểm trước đó vì mọi thứ vẫn chưa rõ ràng. | AA3: 40 | AB3: 30 | AC3: 30 | AD3: Luật sư | AE3: =SUM(AA3:AC3) -> 100
A4: 46015.447 | B4: Nam | C4: 40 - 49 | D4: Thành thị | E4: Đại học | F4: Khu vực phi chính thức (Lao động tự do, không có HĐLĐ) | G4: Từ 23 - 32 triệu VNĐ | H4: 3 người | I4: 10 | J4: Áp dụng công nghệ định danh, rà soát tài khoản tự động các nguồn thu thông qua yêu cầu bên trung gian thanh toán, phán đoán cá nhân. | K4: 10 | L4: Công nghệ hiện đại | M4: 5 | N4: Vẫn thấy có nhiều khó khăn khi dùng Etax mobile. Chưa rõ phần mềm có cập nhật, thay đổi theo chính sách mới hay không. | O4: 7 | P4: Chưa làm theo quy định mới nhưng từ truyền thông giải thích thì cảm giác có sự tốt hơn | Q4: 7 | R4: Vì còn mới và chưa triển khai, nên phỏng đoán sẽ tốt hơn cách làm trước đây. Dựa trên kinh nghiệm từ quá khứ thì mọi thứ vẫn làm tốt, nhưng chưa chắc tương lai thế nào vì không biết quá trình chuyển đổi thế nào. | S4: 6 | T4: Do sức mua bị giảm bởi lạm phát do cung tiền cho các dự án quốc gia, nên cảm thấy 6/10. Thay đổi chưa phù hợp với mức sống thực tế. | U4: 5 | V4: Tính hiệu quả từ tiền thuế thu được chưa được minh bạch và giải trình đầy đủ, còn nhiều vụ án tham nhũng khi triển khai dự án công, trong đó có phần tiền thuế đóng góp. | W4: 6 | X4: Chỉ tham khảo từ nguồn truyền thông. Chưa thấy thông tin từ cơ quan thuế, giới học thuật (sách vở). | Y4: 7 | Z4: Đóng thuế ít hơn, các khung thuế cũng đơn giản hơn. Nhưng tổng thể không đáp ứng được mong đợi so với thực mức sống thực tế. Tuy nhiên, sẽ ủng hộ nếu thu thuế tốt cho cả quốc gia nếu xài tiền thuế thu được hiệu quả. | AA4: 50 | AB4: 20 | AC4: 30 | AD4: Luật sư | AE4: =SUM(AA4:AC4) -> 100
A5: 46015.471 | B5: Nữ | C5: 40 - 49 | D5: Thành thị | E5: Sau Đại học | F5: Khu vực chính thức (Có Hợp đồng lao động, đóng BHXH) | G5: Từ 70 - 102 triệu VNĐ | H5: 2 người | I5: 6 | J5: Người có thu nhập phi chính thức còn nhiều và Nhà nước hiện nay chưa quản lý được. | K5: 5 | L5: Hiện nay các khoản doanh thu bán lẻ không xuất hóa đơn vẫn còn cao, như doanh thu bán lẻ, cái này chưa có công nghệ quản lý. | M5: 2 | N5: Thủ tục khai báo phức tạp, tôi phải thường nhờ dịch vụ làm thì sẽ thuận tiện, nhanh chóng hơn. Còn người dân bình thường sẽ khó xử lý vì không có mối quan hệ để hỏi người chịu trách nhiệm chính, hỗ trợ. | O5: 7 | P5: Đơn giản hơn vì nó ít bậc hơn. | Q5: 7 | R5: Tôi hi vọng thế. Hiện tại, Nhà nước cũng đang cố gắng minh bạch, đưa ra nhiều chính sách cải tiến để giúp việc thực thi chính sách tốt hơn. | S5: 7 | T5: Mức giảm trừ được nâng lên, và các bậc thuế cũng thấp hơn. Tuy nhiên, chưa phản ánh đúng với thực tế, mức sống hiện nay. | U5: 5 | V5: Tôi không quá tin vào điều này vì hàng năm vẫn thấy sự thất thoát, tuy nhiên tôi tin năng lực quản lý nhà nước sẽ tăng lên. | W5: 7 | X5: Nó được lấy ý kiến từ người dân và công khai thông tin rõ ràng. Truyền thông rõ ràng từng chặng, từng bước quá trình luật hình thành. | Y5: 8 | Z5: Vì đóng thuế là nghĩa vụ công dân để xây dựng đất nước và mức thuế này cũng hợp lý. Tuy nhiên, chưa phản ánh hoàn toàn thực tế hiện nay. | AA5: 30 | AB5: 40 | AC5: 30 | AD5: Nhân viên văn phòng - Chuyên viên ngân hàng | AE5: =SUM(AA5:AC5) -> 100
A6: 46015.502 | B6: Nữ | C6: 40 - 49 | D6: Thành thị | E6: Đại học | F6: Khu vực chính thức (Có Hợp đồng lao động, đóng BHXH) | G6: Trên 102 triệu VNĐ | H6: 2 người | I6: 8 | J6: Khi cảm giác về gánh nặng thuế giảm sẽ khuyến khích người đóng thuế tích cực kê khai nộp thuế hơn. Hiện nay, cơ quan thuế cũng đang triển khai rất quyết liệt, nhanh và hiệu quả. | K6: 8 | L6: Qua kinh nghiệm hệ thống hoá đơn điện tử từ VAT hay thuế DN thì làm rất hiệu quả. Hiện nay, cơ quan thuế cũng đang triển khai rất quyết liệt, nhanh và hiệu quả. | M6: 8 | N6: Không khai báo trực tiếp nên không trả lời được chính xác. Do công ty đóng nên chưa nhiều trải nghiệm. Nghe qua một vài chia sẻ thì thấy tích cực, tốt. Tuy nhiên, trong quá khứ thì có trải nghiệm chưa tốt, dù hiện tại trải nghiệm tốt hơn từ chia sẻ bạn bè, người thân. Có sự cải tiến nhiều. | O6: 9 | P6: Có sự giãn cách giữa các bậc. Cơ bản cũng không quan tâm nhiều do nhân sự, kế toán làm hết rồi. Qua truyền thông, báo chí thì thấy có sự đơn giản, dễ hiểu. | Q6: 6 | R6: Hiện mới chỉ nắm được người có tóc, chưa xử lý được những người nằm ngoài tầm kiểm soát hay khó quản lý. Chưa có chính sách khuyến khích người thu nhập cao chủ động khai báo thuế, minh bạch các nguồn thu. | S6: 7 | T6: Tương tự câu trên, mới nắm được người có tóc | U6: 5 | V6: Chưa “cảm nhận” được. Không biết tiền đi đâu, về đâu, làm gì. Vẫn thấy được nguồn thu được sử dụng nhưng vấn đề là chưa rõ ràng, chưa thấy hiệu quả, minh bạch. | W6: 8 | X6: Đọc nhiều tin bài, hội thảo, truyền thông tốt, giải thích dễ hiểu. | Y6: 8 | Z6: Buộc phải tuân thủ nhưng kỳ vọng có chính sách bao trùm hơn. Chính sách mới có những nỗ lực điều chỉnh tích cực hơn nhưng vẫn chưa hướng tới được những người có thu nhập đáng lẽ chịu thuế phải tự động khai báo thay vì phải đi thanh tra, xử phạt. Phải có cơ chế thưởng phạt. Hiện tại chỉ dừng lại ở phạt, chưa có chính sách khuyến khích. | AA6: 30 | AB6: 40 | AC6: 30 | AD6: Nhân viên văn phòng - Giám đốc đối ngoại | AE6: =SUM(AA6:AC6) -> 100
A7: 46015.914 | B7: Nam | C7: 40 - 49 | D7: Thành thị | E7: Sau Đại học | F7: Khu vực phi chính thức (Lao động tự do, không có HĐLĐ) | G7: Từ 32 - 48 triệu VNĐ | H7: 3 người | I7: 6 | J7: Bậc thuế và mức thuế này vẫn là quá cao, làm giảm động lực làm việc và tăng khả năng gian lận. Sự thay đổi không nhiều so với trước đây với những người có thu nhập cao. | K7: 7 | L7: Nếu áp dụng công nghệ thì việc thực thi sẽ dễ dàng, không khó khăn. Tuy nhiên, trong quá trình thực thi, bằng nhiều cách thức, đối tượng có thể thoát được thuế, đặc biệt thông qua lạm dụng quyền và lợi ích nhóm, trong đó có lao động ở các cơ quan nhà nước có khả năng tự ra luật để mình được đặc quyền. | M7: 5 | N7: Tôi thấy cơ quan thuế Quận 7 thật tệ. Ngoài ra, đang trong quá trình chuyển đổi, sáp nhập nên khâu thực thi, hỗ trợ người dân gặp nhiều khó khăn. Và còn có nhiều vấn đề tiêu cực, nhũng nhiễu, gây khó khăn cho người dân. Tuy nhiên, đây là trải nghiệm cá nhân ở một cơ quan, chưa thể đánh giá toàn bộ hệ thống nên nếu chấm điểm quá thấp thì sẽ không công bằng. Vì thế cho điểm trung bình. | O7: 8 | P7: Đồng ý khi có sự thay đổi tốt hơn. | Q7: 6 | R7: Cái này là hy vọng thôi chứ trong giai đoạn nhiều chuyển đổi này thì tôi lo là sẽ nhiều khó khăn và phúc tạp ngoài mong đợi. Vẫn phải chờ đợi thêm. | S7: 3 | T7: Mức và biểu thuế hiện vẫn quá cao, làm giảm động lực làm việc, đặc biệt của tầng lớp trung lưu, không phản ánh đúng với thực tế, mức sống của người dân. Ngoài ra, không phản ánh đúng theo từng vùng. Người dân ở các thành phố lớn có chi phí sống cao hơn nhưng vẫn phải đóng thuế giống với người dân ở các vùng có chi phí sống thấp hơn. | U7: 5 | V7: Tôi lo ngại về hiệu quả đầu tư công của Việt Nam từ xưa đến nay. Có những trải nghiệm không tốt, tiêu cực về các dự án, tài sản công bị thất thoát, lãng phí, tham nhũng. Người dân cũng không được tham gia phản biện vào các dự án lớn và không biết đồng thuế có sử dụng hiệu quả, đúng mục đích hay không. Tuy nhiên, so với các nước kém phát triển, nghèo đói khác thì vẫn có tín hiệu tích cực, tiền thuế vẫn được sử dụng chứ không quá tồi tệ. Sống thì buộc phải hy vọng thôi. | W7: 5 | X7: Có ai hỏi tôi về cải cách thuế này đâu. Vấn đề truyền thông còn hạn chế nên cho điểm trung bình. | Y7: 6 | Z7: Tôi không ủng hộ lắm nhưng sẽ tuân thủ. Trừ 2 điểm thiết kế và trừ 2 điểm thực thi. | AA7: 30 | AB7: 40 | AC7: 30 | AD7: Lao động tự do | AE7: =SUM(AA7:AC7) -> 100
A8: 46016.361 | B8: Nữ | C8: 40 - 49 | D8: Thành thị | E8: Sau Đại học | F8: Khu vực chính thức (Có Hợp đồng lao động, đóng BHXH) | G8: Từ 32 - 48 triệu VNĐ | H8: 2 người | I8: 6 | J8: Cần thêm thu nhập của tổ chức/cá nhân chịu thuế phải rõ ràng, minh bạch. Để phát hiện được hành vi gian lận, trốn thuế thì phải đi từ đầu vào là đo kiểm được thu nhập của tổ chức/cá nhân - nó giải thích cho niềm tin không cao vì lý do này. | K8: 7 | L8: Tôi chỉ nhận định chủ quan trên cơ sở nhà nước đã thu được thuế gia tăng trong thời gian gần đây | M8: 7 | N8: Thủ tục hoàn thuế đơn giản hơn | O8: 7 | P8: Đối với cá nhân tôi thi tôi cảm thấy có đơn giản hơn, tuy nhiên với tổ chức khi phải hỗ trợ ưu đãi thuế cho những cá nhân thuộc đối tượng miễn giảm (nhà khoa hoc, nghiên cứu,...) thì vẫn còn sự phức tạp trong kê khai (thông tin này được nghe phản ánh lại từ bộ phận hỗ trợ thuế) | Q8: 8 | R8: Niềm tin cá nhân đối với chính sách của nhà nước | S8: 5 | T8: Mức giảm trừ gia cảnh nên được điều chỉnh theo khu vực sinh sống, phù hợp hơn với thực tế. | U8: 5 | V8: Nhà nước cần công khai minh bạch dữ liệu thu thuế và đầu tư công tùy theo thẩm quyền quản lý để người dân được biết và giám sát theo quy định pháp luật. Thường thì chọn trung bình là mức trung tính trong những vấn đề còn băn khoăn | W8: 7 | X8: Cảm nhận cá nhân. Cảm thấy truyền thông về thuế TNCN trong thời gian qua có tốt hơn. | Y8: 8 | Z8: Trách nhiệm công dân nên ủng hộ. | AA8: 30 | AB8: 30 | AC8: 40 | AD8: Cán bộ, công chức, viên chức | AE8: =SUM(AA8:AD8) -> 100
A9: 46016.397 | B9: Nữ | C9: 30 - 39 | D9: Thành thị | E9: Sau Đại học | F9: Khu vực chính thức (Có Hợp đồng lao động, đóng BHXH) | G9: Trên 102 triệu VNĐ | H9: 2 người | I9: 10 | J9: Hoàn toàn đồng ý. Chính phủ tăng cường kiểm soát giao dịch ngân hàng để minh bạch dòng tiền cá nhân và chống rửa tiền. | K9: 8 | L9: Khi làm việc với cơ quan thuế thì biết rằng cơ quan thuế đang có những công cụ, phần mềm hỗ trợ kiểm tra thuế cũng như truy cập được nhiều nguồn dữ liệu khác nhau. Tuy nhiên, các phần mềm của chính phù hiện nay chưa được tối ưu, một số doanh nghiệp vẫn có cách trốn thuế. | M9: 4 | N9: Hiện tại phần mềm khai thuế vẫn chưa được friendly và hay gặp lỗi, trải nghiệm không tốt. Phải thuê người làm giúp. Gặp vấn đề thì không biết hỏi ai. | O9: 7 | P9: 5 bậc sẽ ít hơn 7 bậc tuy nhiên mức giảm trừ gia cảnh chưa hợp lý, chưa sát với thực tế. Chưa phản ánh những vấn đề như nuôi con, vay tiền mua nhà, vay ngân hàng. | Q9: 5 | R9: Chính phủ đang siết chặt thu thuế, trong khi đó chưa áp dụng các chính sách hỗ trợ người dân giảm trừ như mua nhà, con đi học. Chưa có đánh giá tác động cho các nhóm đối tượng khác nhau cũng như đánh giá tác động trong tương lai. | S9: 5 | T9: Tôi chưa tính được khi áp dụng thuế mới mức đóng cụ thể là bao nhiêu. Không thay đổi khi chính sách mới áp dụng. | U9: 5 | V9: Chưa chắc, k có niềm tin lắm nhưng vẫn có niềm tin. Vẫn đánh giá thuế có sử dụng cho dịch vụ công. Chính phủ có lắng nghe phản hồi của người dân, có một chút thay đổi. Vì thế cho điểm số ở mức trung bình. | W9: 5 | X9: Mục tiêu chính thì hiểu, rationale đưa ra ngưỡng thì chưa hiểu lắm, Chính phủ cũng chưa forseen được mức trượt giá, lạm phát + giảm trừ gia cảnh. | Y9: 6 | Z9: Không ủng hộ cũng k được. | AA9: 45 | AB9: 25 | AC9: 30 | AD9: Nhân viên văn phòng - Bất động sản | AE9: =SUM(AA9:AC9) -> 100
A10: 46016.639 | B10: Nữ | C10: 30 - 39 | D10: Thành thị | E10: Đại học | F10: Khu vực chính thức (Có Hợp đồng lao động, đóng BHXH) | G10: Từ 70 - 102 triệu VNĐ | H10: 1 người | I10: 7 | J10: Nếu là người lao động trong nhóm chính thức thì thực sự dễ dàng quản lý và cũng khó để trốn thuế, tuy nhiên 2 nhóm còn lại ở khu vực tự do và đã nghỉ hưu thì điều này không thể chắc chắn. Niềm tin chỉ ở mức tương đối. | K10: 7 | L10: Sẽ có thể phát hiện nhưng không thể toàn bộ và ngay lập tức, vì những doanh nghiệp không tuân thủ quy định thì nếu có cơ quan thuế sẽ phải tiến hành điều tra chứ không có hệ thống để nhận diện hành vi vi phạm ngay lập tức. | M10: 5 | N10: Tôi không rõ vấn đề này vì có bộ phận kế toán/nhân sự của công ty xử lý giúp. Chưa có trải nghiệm gì với cơ quan thuế. | O10: 7 | P10: Thực ra thì phương thức lũy tiến như nhau, nhưng giản lược số bậc thuế, và giảm tỷ lệ đóng thì tốt cho người lao động. Cá nhân đóng thuế ít hơn so với trước đây. | Q10: 7 | R10: Nhà nước có chủ động điều chỉnh chính sách thuế mới, như vậy là rất tốt. tuy nhiên cần sự phối hợp của doanh nghiệp thì chính sách thuế mới thực sự hiệu quả. Các doanh nghiệp FDI thì có thể đảm bảo nhưng băn khoăn về các doanh nghiệp SME, doanh nghiệp trong nước hoặc các hộ kinh doanh. Ngoài ra, vấn đề khi thực thi có phụ thuộc vào các cấp cơ quan nhà nước ở dưới, nhỏ hơn có thể không thực hiện đúng với chính sách đề ra. | S10: 8 | T10: Thấp hơn thì sẽ tốt hơn, hiện giờ mức đóng vẫn cao nhưng, giảm trừ gia cảnh và cá nhân còn khá thấp so với mức sống của khu vực thành thị. đặc biệt nhóm người chưa sở hữu nhà riêng. Cá nhân cảm thấy hài lòng vì giảm được thuế so với trước đây. | U10: 6 | V10: Tôi không thấy rằng giữa người đóng thuế cao và thấp có sự khác biệt trong việc hưởng các dịch vụ công tốt hơn, tất cả là như nhau. và qua các năm thì dịch vụ y tế hay đường xá đều không thay đổi dù tiền thuế đóng nhiều hơn, thông qua ở TPHCM hầu như không có nhiều cải thiện về đầu tư hạ tầng công, các trung tâm khám chữa bệnh công chất lượng hơn hay các trung tâm giải trí, bảo tàng nghệ thuật miễn phí cho người dân, hầu hết đều thu phí, và chất lượng không tốt. Mặc dù không hài lòng nhưng nhìn nhận thực tế vì có sự cải thiện, đặc biệt là có Metro ở Hồ Chí Minh. | W10: 5 | X10: Tôi thấy ko quá cần thiết, vì cơ bản là có cải thiện cho đối tượng thu nhập của tôi. tuy nhiên việc sử dụng thuế vào đâu thì cần làm rõ. Không theo dõi quá trình chính sách để hình thành nên không nắm rõ thông tin. Quan trọng là giảm thuế thì cũng không cần giải thích nhiều. | Y10: 7 | Z10: Là công dân thì phải tuân thủ theo quy định tuyệt đối nhưng về mặt ủng hộ thì ở mức khá. | AA10: 60 | AB10: 15 | AC10: 25 | AD10: Nhân viên văn phòng - Bất động sản | AE10: =SUM(AA10:AD10) -> 100
A11: 46019.633 | B11: Nữ | C11: 30 - 39 | D11: Nông thôn | E11: Sau Đại học | F11: Khu vực phi chính thức (Lao động tự do, không có HĐLĐ) | G11: Từ 23 - 32 triệu VNĐ | H11: 3 người | I11: 5 | J11: Tôi tin rằng nếu đã có Luật thì ai muốn trốn sẽ có cách lách để k bị phát hiện | K11: 8 | L11: Do họ có thể truy thu dựa vào dòng tiền ra vào tài khoản | M11: 10 | N11: Có thể làm online, nên tôi thấy tiện a | O11: 5 | P11: Tôi thấy như nhau | Q11: 9 | R11: Tại cán bộ thuế ở tôi rất tốt ạ | S11: 2 | T11: Tôi thấy phần trăm đóng thuế còn cao so với tôi | U11: 7 | V11: Dạ do tôi dễ tin người ạ | W11: 8 | X11: Dạ, về cơ bản là đã khá chi tiết và rõ ràng ạ | Y11: 10 | Z11: Dạ, là công dân thì phải tuân thủ, vì không có phương án khác ạ | AA11: 30 | AB11: 40 | AC11: 30 | AD11: Influencer | AE11: =SUM(AA11:AD11) -> 100
A12: 46019.724 | B12: Nữ | C12: 40 - 49 | D12: Thành thị | E12: Sau Đại học | F12: Khu vực chính thức (Có Hợp đồng lao động, đóng BHXH) | G12: Trên 102 triệu VNĐ | H12: 2 người | I12: 4 | J12: Vì tham nhũng, nhũng nhiễu | K12: 5 | L12: Vì hệ thống và luật định còn mơ hồ, nhiều kẽ hỡ | M12: 6 | N12: Quy trình đơn giản hơn, nhưng hệ thống vẫn chưa kiện toàn, nhân sự chưa sắp xếp ổn | O12: 5 | P12: Không khác lắm | Q12: 4 | R12: Với tôi, thuế vẫn đang nắm trên những người tầng lớp trung lưu, làm công ăn lương | S12: 2 | T12: Mức bắt đầu đóng thuế ở mỗi mức quá cao so với mặt bằng chung trong khu vực | U12: 2 | V12: Tham nhũng, không minh bạch, | W12: 6 | X12: Đã giải thích nhưng không thuyết phục, chủ yếu là thiếu data support cho việc ra quyết định | Y12: 5 | Z12: Tôi tuân thủ, nhưng với tôi mức thuế hiện tại đang đóng quá cao, trong khi lạm phát đang phi mã | AA12: 45 | AB12: 35 | AC12: 20 | AD12: Nhân viên văn phòng - Dược | AE12: =SUM(AA12:AD12) -> 100
A13: 46019.742 | B13: Nam | C13: 30 - 39 | D13: Thành thị | E13: Đại học | F13: Khu vực chính thức (Có Hợp đồng lao động, đóng BHXH) | G13: Từ 12 - 18 triệu VNĐ | H13: 1 người | I13: 8 | J13: Nếu Nhà nước số hóa dần, nộp thuế trên ETax thì và có barem cụ thể thì khả năng gian lận sẽ giảm xuống, tuy nhiên có thể đang trong quá trình làm nên vẫn cần thêm thời gian. | K13: 6 | L13: Tôi có lòng tin chưa cao lắm với Nhà nước trong nhiều vấn đề, trong đó có vấn đề công nghệ. | M13: 9 | N13: Cái này thì tôi thấy có cải thiện, do 2 năm khai thuế bằng ETax thì tiện hơn. | O13: 8 | P13: Tôi thấy logic cơ bản thì ko khác gì, chỉ điều chỉnh mốc con số nên về tính đơn giản, dễ hiểu, dễ thực hiện thì vẫn không thay đổi, nhưng cách tính thì vẫn khá dễ hiểu. | Q13: 7 | R13: Tôi ko có cơ sở nào nhưng lòng tin thì ở mức trung bình khá. | S13: 8 | T13: Tôi thấy điều chỉnh theo hướng cải thiện nên vẫn ok. | U13: 4 | V13: Tôi không tin tưởng việc này, nhìn thấy dịch vụ và hàng hóa công ở mức trung bình đến tệ. | W13: 6 | X13: Tôi thấy cũng có chia sẻ, truyền thông báo chí về việc này nên cũng tạm ok. | Y13: 7 | Z13: Tôi ủng hộ vì nhìn chung mức thuế suất có điều chỉnh tốt hơn; vấn đề còn lại là Nhà nước dùng thuế hiệu quả đến đâu thôi. | AA13: 35 | AB13: 45 | AC13: 20 | AD13: Chủ doanh nghiệp | AE13: =SUM(AA13:AD13) -> 100
A14: 46019.767 | B14: Nữ | C14: 40 - 49 | D14: Thành thị | E14: Đại học | F14: Khu vực chính thức (Có Hợp đồng lao động, đóng BHXH) | G14: Trên 102 triệu VNĐ | H14: 1 người | I14: 8 | J14: Thực tế cơ quan thuế dễ dàng phát hiện hạng vi gian lận thuế không phải đến từ các qui định của Luật Thuế TNCN mà đến từ cách triển khai, tuyên truyền ở bước thực thi: áp dụng công nghệ, data cross - check, thanh tra thuế, CQĐT . | K14: 9 | L14: Khuyến khích hành vi tiêu dùng cashless của cá nhân, siết chặt các giao dịch cash của hộ kinh doanh cá thể và DN | M14: 5 | N14: Trang web cau co quan thue vẫn chưa hỗ trợ chức năngtruy suất thông tin lịch sử về hồ sơ kê khai và nộp thúe cá nhân ( chỉ kiểm tra được các thông tin cơ bản, không thể hiênn chi tiết như Canada/ Mỹ) | O14: 8 | P14: Bậc tính thuế ít hơn --> tính toán đơn giản hơn. | Q14: 5 | R14: Không có cơ sở để tin việc này, vì hiện nay các loại dữ liệu để support cơ quan thuế kiểm tra việc tuân thủ thuế chưa đồng bộ giữa các địa phương và các ngành --> nên nếu công dân nào làm trong lĩnh vực buộc phải tuân thủ thì tuân thủ, sống ở địa phương nào mà cơ quan thuế làm gắt hơn thi sẽ nộp thuế đầy đủ hơn.. | S14: 5 | T14: Mức thuế hợp lý nhưng nói công bằng thì không hẳn, nhưu đã nói trên, tuỳ vào linh vực và địa bàn sinh sống thì mức độ nộp thuế khác nhau ( do cơ quan thực thi quyết định) | U14: 5 | V14: Luật ngân sách của VN không phản ánh được điều này, đại biểu QH VN không có nhiều cơ hội để phản biện ngân sách QG một cách phù hợp | W14: 6 | X14: Theo quy định của Luật Ban hành VB pháp luật, Bộ TC đã giải thích đầy đủ nhưng không thuyết phục. | Y14: 9 | Z14: Tôi không có cơ hội để không tuân thủ | AA14: 60 | AB14: 30 | AC14: 10 | AD14: Nhân viên văn phòng - Luật | AE14: =SUM(AA14:AD14) -> 100
