Workbook

Sheet Summary
A1: Interview - Summary
A2: Metric | B2: MAE (Intensity) | C2: Agreement Rate (%) | D2: MCC | E2: TVD | F2: EMD | G2: Human_Oppose (%) | H2: Human_Neutral (%) | I2: Human_Support (%) | J2: AI_Oppose (%) | K2: AI_Neutral (%) | L2: AI_Support (%)
A3: ENF1 | B3: 1.304 | C3: 0.56 | D3: 0.36628779 | E3: 0.32 | F3: 0.824 | G3: 0.12 | H3: 0.44 | I3: 0.44 | J3: 0.28 | K3: 0.6 | L3: 0.12
A4: ENF2 | B4: 1.328 | C4: 0.56 | D4: 0.22315185 | E4: 0.24 | F4: 0.912 | G4: 0 | H4: 0.6 | I4: 0.4 | J4: 0.2 | K4: 0.64 | L4: 0.16
A5: FAC1 | B5: 1.8 | C5: 0.6 | D5: 0.30254174 | E5: 0.16 | F5: 1.56 | G5: 0.2 | H5: 0.52 | I5: 0.28 | J5: 0.04 | K5: 0.68 | L5: 0.28
A6: FAC2 | B6: 1.544 | C6: 0.56 | D6: 0.15179083 | E6: 0.04 | F6: 1.208 | G6: 0.04 | H6: 0.52 | I6: 0.44 | J6: 0 | K6: 0.52 | L6: 0.48
A7: TRU1 | B7: 1.184 | C7: 0.56 | D7: 0.067299764 | E7: 0.12 | F7: 0.624 | G7: 0.12 | H7: 0.64 | I7: 0.24 | J7: 0.12 | K7: 0.76 | L7: 0.12
A8: TRU2 | B8: 1.488 | C8: 0.6 | D8: 0.300764 | E8: 0.12 | F8: 1.328 | G8: 0.16 | H8: 0.52 | I8: 0.32 | J8: 0.04 | K8: 0.6 | L8: 0.36
A9: TRU3 | B9: 1.456 | C9: 0.72 | D9: 0.50390326 | E9: 0.28 | F9: 1.408 | G9: 0.24 | H9: 0.6 | I9: 0.16 | J9: 0 | K9: 0.88 | L9: 0.12
A10: TRU4 | B10: 0.864 | C10: 0.8 | D10: 0.56617647 | E10: 0.12 | F10: 0.464 | G10: 0 | H10: 0.68 | I10: 0.32 | J10: 0.08 | K10: 0.72 | L10: 0.2
A11: OUT1 | B11: 1.04 | C11: 0.88 | D11: 0.75664445 | E11: 0.04 | F11: 0.768 | G11: 0 | H11: 0.44 | I11: 0.56 | J11: 0 | K11: 0.4 | L11: 0.6
A14: Validation - Summary
A15: Metric | B15: MAE (Intensity) | C15: Agreement Rate (%) | D15: MCC | E15: TVD | F15: EMD | G15: Human_Oppose (%) | H15: Human_Neutral (%) | I15: Human_Support (%) | J15: AI_Oppose (%) | K15: AI_Neutral (%) | L15: AI_Support (%)
A16: ENF1 | B16: ='Validation - Summary'!B3 -> 1.9151365 | C16: ='Validation - Summary'!C3 -> 0.43424318 | D16: ='Validation - Summary'!D3 -> 0.00097789611 | E16: ='Validation - Summary'!E3 -> 0.24218362 | F16: ='Validation - Summary'!F3 -> 0.95434243 | G16: ='Validation - Summary'!G3 -> 0.13647643 | H16: ='Validation - Summary'!H3 -> 0.44665012 | I16: ='Validation - Summary'!I3 -> 0.41687345 | ... L16: ='Validation - Summary'!L3 -> 0.29875931
A17: ENF2 | B17: ='Validation - Summary'!B4 -> 1.898263 | C17: ='Validation - Summary'!C4 -> 0.42452131 | D17: ='Validation - Summary'!D4 -> -0.027270302 | E17: ='Validation - Summary'!E4 -> 0.11092676 | F17: ='Validation - Summary'!F4 -> 0.73647643 | G17: ='Validation - Summary'!G4 -> 0.11166253 | H17: ='Validation - Summary'!H4 -> 0.41191067 | I17: ='Validation - Summary'!I4 -> 0.4764268 | ... L17: ='Validation - Summary'!L4 -> 0.4712023
A18: FAC1 | B18: ='Validation - Summary'!B5 -> 2.5975186 | C18: ='Validation - Summary'!C5 -> 0.3838043 | D18: ='Validation - Summary'!D5 -> 0.026828823 | E18: ='Validation - Summary'!E5 -> 0.44158365 | F18: ='Validation - Summary'!F5 -> 2.1890819 | G18: ='Validation - Summary'!G5 -> 0.20595533 | H18: ='Validation - Summary'!H5 -> 0.43920596 | I18: ='Validation - Summary'!I5 -> 0.35483871 | ... L18: ='Validation - Summary'!L5 -> 0.79642235
A19: FAC2 | B19: ='Validation - Summary'!B6 -> 1.8843672 | C19: ='Validation - Summary'!C6 -> 0.49254842 | D19: ='Validation - Summary'!D6 -> 0.025662422 | E19: ='Validation - Summary'!E6 -> 0.47442934 | F19: ='Validation - Summary'!F6 -> 1.546402 | G19: ='Validation - Summary'!G6 -> 0.052109181 | H19: ='Validation - Summary'!H6 -> 0.45905707 | I19: ='Validation - Summary'!I6 -> 0.48883375 | ... L19: ='Validation - Summary'!L6 -> 0.96326309
A20: TRU1 | B20: ='Validation - Summary'!B7 -> 2.1002481 | C20: ='Validation - Summary'!C7 -> 0.43547971 | D20: ='Validation - Summary'!D7 -> 0.028032426 | E20: ='Validation - Summary'!E7 -> 0.2164971 | F20: ='Validation - Summary'!F7 -> 1.4168734 | G20: ='Validation - Summary'!G7 -> 0.14143921 | H20: ='Validation - Summary'!H7 -> 0.54094293 | I20: ='Validation - Summary'!I7 -> 0.31761787 | ... L20: ='Validation - Summary'!L7 -> 0.53411496
A21: TRU2 | B21: ='Validation - Summary'!B8 -> 2.462531 | C21: ='Validation - Summary'!C8 -> 0.37866404 | D21: ='Validation - Summary'!D8 -> -0.027899709 | E21: ='Validation - Summary'!E8 -> 0.57053157 | F21: ='Validation - Summary'!F8 -> 2.169727 | G21: ='Validation - Summary'!G8 -> 0.17369727 | H21: ='Validation - Summary'!H8 -> 0.44168734 | I21: ='Validation - Summary'!I8 -> 0.38461538 | ... L21: ='Validation - Summary'!L8 -> 0.95514696
A22: TRU3 | B22: ='Validation - Summary'!B9 -> 2.462531 | C22: ='Validation - Summary'!C9 -> 0.40009057 | D22: ='Validation - Summary'!D9 -> 0.019436244 | E22: ='Validation - Summary'!E9 -> 0.2980784 | F22: ='Validation - Summary'!F9 -> 1.88933 | G22: ='Validation - Summary'!G9 -> 0.17866005 | H22: ='Validation - Summary'!H9 -> 0.53846154 | I22: ='Validation - Summary'!I9 -> 0.28287841 | ... L22: ='Validation - Summary'!L9 -> 0.58095681
A23: TRU4 | B23: ='Validation - Summary'!B10 -> 1.9776675 | C23: ='Validation - Summary'!C10 -> 0.43646233 | D23: ='Validation - Summary'!D10 -> 6.0542354e-05 | E23: ='Validation - Summary'!E10 -> 0.22042527 | F23: ='Validation - Summary'!F10 -> 1.2610422 | G23: ='Validation - Summary'!G10 -> 0.11414392 | H23: ='Validation - Summary'!H10 -> 0.58312655 | I23: ='Validation - Summary'!I10 -> 0.30272953 | ... L23: ='Validation - Summary'!L10 -> 0.5231548
A24: OUT1 | B24: ='Validation - Summary'!B11 -> 2.2486352 | C24: ='Validation - Summary'!C11 -> 0.43669046 | D24: ='Validation - Summary'!D11 -> 0.014769023 | E24: ='Validation - Summary'!E11 -> 0.52734778 | F24: ='Validation - Summary'!F11 -> 1.9225806 | G24: ='Validation - Summary'!G11 -> 0.086848635 | H24: ='Validation - Summary'!H11 -> 0.48138958 | I24: ='Validation - Summary'!I11 -> 0.43176179 | ... L24: ='Validation - Summary'!L11 -> 0.95910956
A27: Calibration - Summary
A28: Metric | B28: MAE (Intensity) | C28: Agreement Rate (%) | D28: MCC | E28: TVD | F28: EMD | G28: Human_Oppose (%) | H28: Human_Neutral (%) | I28: Human_Support (%) | J28: AI_Oppose (%) | K28: AI_Neutral (%) | L28: AI_Support (%)
A29: ENF1 | B29: ='Calibration - Summary'!B3 -> 1.8471464 | C29: ='Calibration - Summary'!C3 -> 0.43473945 | D29: ='Calibration - Summary'!D3 -> 0.00097132092 | E29: ='Calibration - Summary'!E3 -> 0.23970223 | F29: ='Calibration - Summary'!F3 -> 1.4143921 | G29: ='Calibration - Summary'!G3 -> 0.13647643 | H29: ='Calibration - Summary'!H3 -> 0.44665012 | I29: ='Calibration - Summary'!I3 -> 0.41687345 | ... L29: ='Calibration - Summary'!L3 -> 0.30173697
A30: ENF2 | B30: ='Calibration - Summary'!B4 -> 1.8377171 | C30: ='Calibration - Summary'!C4 -> 0.45856079 | D30: ='Calibration - Summary'!D4 -> 0.033905287 | E30: ='Calibration - Summary'!E4 -> 0.1439206 | F30: ='Calibration - Summary'!F4 -> 1.6401985 | G30: ='Calibration - Summary'!G4 -> 0.11166253 | H30: ='Calibration - Summary'!H4 -> 0.41191067 | I30: ='Calibration - Summary'!I4 -> 0.4764268 | ... L30: ='Calibration - Summary'!L4 -> 0.44764268
A31: FAC1 | B31: ='Calibration - Summary'!B5 -> 2.4456576 | C31: ='Calibration - Summary'!C5 -> 0.39007444 | D31: ='Calibration - Summary'!D5 -> 0.0091640253 | E31: ='Calibration - Summary'!E5 -> 0.25756824 | F31: ='Calibration - Summary'!F5 -> 1.9255583 | G31: ='Calibration - Summary'!G5 -> 0.20595533 | H31: ='Calibration - Summary'!H5 -> 0.43920596 | I31: ='Calibration - Summary'!I5 -> 0.35483871 | ... L31: ='Calibration - Summary'!L5 -> 0.60942928
A32: FAC2 | B32: ='Calibration - Summary'!B6 -> 1.6908189 | C32: ='Calibration - Summary'!C6 -> 0.46423466 | D32: ='Calibration - Summary'!D6 -> -0.021171245 | E32: ='Calibration - Summary'!E6 -> 0.18943002 | F32: ='Calibration - Summary'!F6 -> 0.75682382 | G32: ='Calibration - Summary'!G6 -> 0.052109181 | H32: ='Calibration - Summary'!H6 -> 0.45905707 | I32: ='Calibration - Summary'!I6 -> 0.48883375 | ... L32: ='Calibration - Summary'!L6 -> 0.67826377
A33: TRU1 | B33: ='Calibration - Summary'!B7 -> 2.0099256 | C33: ='Calibration - Summary'!C7 -> 0.45035739 | D33: ='Calibration - Summary'!D7 -> -0.018752202 | E33: ='Calibration - Summary'!E7 -> 0.12108811 | F33: ='Calibration - Summary'!F7 -> 0.8808933 | G33: ='Calibration - Summary'!G7 -> 0.14143921 | H33: ='Calibration - Summary'!H7 -> 0.54094293 | I33: ='Calibration - Summary'!I7 -> 0.31761787 | ... L33: ='Calibration - Summary'!L7 -> 0.31827463
A34: TRU2 | B34: ='Calibration - Summary'!B8 -> 2.0818859 | C34: ='Calibration - Summary'!C8 -> 0.42800637 | D34: ='Calibration - Summary'!D8 -> 0.016688063 | E34: ='Calibration - Summary'!E8 -> 0.22563732 | F34: ='Calibration - Summary'!F8 -> 1.101737 | G34: ='Calibration - Summary'!G8 -> 0.17369727 | H34: ='Calibration - Summary'!H8 -> 0.44168734 | I34: ='Calibration - Summary'!I8 -> 0.38461538 | ... L34: ='Calibration - Summary'!L8 -> 0.31530067
A35: TRU3 | B35: ='Calibration - Summary'!B9 -> 2.1756824 | C35: ='Calibration - Summary'!C9 -> 0.47020974 | D35: ='Calibration - Summary'!D9 -> -0.028228239 | E35: ='Calibration - Summary'!E9 -> 0.25974421 | F35: ='Calibration - Summary'!F9 -> 1.2382134 | G35: ='Calibration - Summary'!G9 -> 0.17866005 | H35: ='Calibration - Summary'!H9 -> 0.53846154 | I35: ='Calibration - Summary'!I9 -> 0.28287841 | ... L35: ='Calibration - Summary'!L9 -> 0.15805749
A36: TRU4 | B36: ='Calibration - Summary'!B10 -> 1.8764268 | C36: ='Calibration - Summary'!C10 -> 0.5432269 | D36: ='Calibration - Summary'!D10 -> 0.030646532 | E36: ='Calibration - Summary'!E10 -> 0.27372531 | F36: ='Calibration - Summary'!F10 -> 0.79404467 | G36: ='Calibration - Summary'!G10 -> 0.11414392 | H36: ='Calibration - Summary'!H10 -> 0.58312655 | I36: ='Calibration - Summary'!I10 -> 0.30272953 | ... L36: ='Calibration - Summary'!L10 -> 0.08250703
A37: OUT1 | B37: ='Calibration - Summary'!B11 -> 1.8987593 | C37: ='Calibration - Summary'!C11 -> 0.45786018 | D37: ='Calibration - Summary'!D11 -> 0.0017808799 | E37: ='Calibration - Summary'!E11 -> 0.15515481 | F37: ='Calibration - Summary'!F11 -> 0.66253102 | G37: ='Calibration - Summary'!G11 -> 0.086848635 | H37: ='Calibration - Summary'!H11 -> 0.48138958 | I37: ='Calibration - Summary'!I11 -> 0.43176179 | ... L37: ='Calibration - Summary'!L11 -> 0.34448917
A40: %Improvement
A41: Metric | B41: MAE (Intensity) | C41: Agreement Rate (%) | D41: MCC | E41: TVD | F41: EMD | G41: Human_Oppose (%) | H41: Human_Neutral (%) | I41: Human_Support (%) | J41: AI_Oppose (%) | K41: AI_Neutral (%) | L41: AI_Support (%)
A42: ENF1 | B42: =((B16-B29)/B16)*100% -> 0.035501425 | C42: =((C29-C16)/C16)*100% -> 0.0011428571 | D42: =ABS(((D29-D16)/D16)*100%) -> 0.0067238158 | E42: =((E16-E29)/E16)*100% -> 0.010245902 | F42: =((F16-F29)/F16)*100% -> -0.48205928
A43: ENF2 | B43: =((B17-B30)/B17)*100% -> 0.031895425 | C43: =((C30-C17)/C17)*100% -> 0.080183206 | D43: =ABS(((D30-D17)/D17)*100%) -> 2.2433044 | E43: =((E17-E30)/E17)*100% -> -0.29743807 | F43: =((F17-F30)/F17)*100% -> -1.2270889
A44: FAC1 | B44: =((B18-B31)/B18)*100% -> 0.05846389 | C44: =((C31-C18)/C18)*100% -> 0.01633681 | D44: =ABS(((D31-D18)/D18)*100%) -> 0.65842612 | E44: =((E18-E31)/E18)*100% -> 0.41671699 | F44: =((F18-F31)/F18)*100% -> 0.12038087
A45: FAC2 | B45: =((B19-B32)/B19)*100% -> 0.10271267 | C45: =((C32-C19)/C19)*100% -> -0.057484228 | D45: =ABS(((D32-D19)/D19)*100%) -> 1.8249901 | E45: =((E19-E32)/E19)*100% -> 0.60072027 | F45: =((F19-F32)/F19)*100% -> 0.5105905
A46: TRU1 | B46: =((B20-B33)/B20)*100% -> 0.043005671 | C46: =((C33-C20)/C20)*100% -> 0.034163901 | D46: =ABS(((D33-D20)/D20)*100%) -> 1.6689468 | E46: =((E20-E33)/E20)*100% -> 0.44069408 | F46: =((F20-F33)/F20)*100% -> 0.37828371
...

Sheet Human - Insights
A1: Demographic Analytics
A2: Human Survey
A3: ENF1 | B3: Oppose | C3: Neutral | D3: Support | E3: =SUM(E4:E5) -> 394 | G3: ENF1 | H3: Oppose | I3: Neutral | J3: Support
A4: Chính thức | B4: 52 | C4: 167 | D4: 158 | E4: 377 | G4: ENF1-Formal | H4: 0.13793103 | I4: 0.44297082 | J4: 0.41909814
A5: Phi chính thức | B5: 2 | C5: 8 | D5: 7 | E5: 17 | G5: ENF1-Informal | H5: 0.11764706 | I5: 0.47058824 | J5: 0.41176471
A7: ENF2 | B7: Oppose | C7: Neutral | D7: Support | E7: =SUM(E8:E9) -> 394 | G7: ENF2 | H7: Oppose | I7: Neutral | J7: Support
A8: Chính thức | B8: 40 | C8: 157 | D8: 180 | E8: 377 | G8: ENF2-Formal | H8: 0.1061008 | I8: 0.41644562 | J8: 0.47745358
A9: Phi chính thức | B9: 3 | C9: 5 | D9: 9 | E9: 17 | G9: ÈNF2-Informal | H9: 0.17647059 | I9: 0.29411765 | J9: 0.52941176
A11: FAC1 | B11: Oppose | C11: Neutral | D11: Support | E11: =SUM(E12:E13) -> 394 | G11: FAC1 | H11: Oppose | I11: Neutral | J11: Support
A12: Chính thức | B12: 73 | C12: 166 | D12: 138 | E12: 377 | G12: Formal | H12: 0.19363395 | I12: 0.4403183 | J12: 0.36604775
A13: Phi chính thức | B13: 7 | C13: 7 | D13: 3 | E13: 17 | G13: Informal | H13: 0.41176471 | I13: 0.41176471 | J13: 0.17647059
A15: FAC2 | B15: Oppose | C15: Neutral | D15: Support | E15: =SUM(E16:E21) -> 403 | G15: FAC2 | H15: Oppose | I15: Neutral | J15: Support
A16: 18 - 24 | B16: 1 | C16: 17 | D16: 37 | E16: 55 | G16: 18 - 24 | H16: 0.018181818 | I16: 0.30909091 | J16: 0.67272727
A17: 25 - 29 | B17: 1 | C17: 36 | D17: 42 | E17: 79 | G17: 25 - 29 | H17: 0.012658228 | I17: 0.4556962 | J17: 0.53164557
A18: 30 - 39 | B18: 8 | C18: 61 | D18: 63 | E18: 132 | G18: 30 - 39 | H18: 0.060606061 | I18: 0.46212121 | J18: 0.47727273
A19: 40 - 49 | B19: 6 | C19: 39 | D19: 34 | E19: 79 | G19: 40 - 49 | H19: 0.075949367 | I19: 0.49367089 | J19: 0.43037975
A20: 50 - 54 | B20: 2 | C20: 17 | D20: 12 | E20: 31 | G20: 50 - 54 | H20: 0.064516129 | I20: 0.5483871 | J20: 0.38709677
A21: 55 - 64 | B21: 3 | C21: 15 | D21: 9 | E21: 27 | G21: 55 - 64 | H21: 0.11111111 | I21: 0.55555556 | J21: 0.33333333
A23: TRU1 | B23: Oppose | C23: Neutral | D23: Support | E23: =SUM(E24:E29) -> 403 | G23: TRU1 | H23: Oppose | I23: Neutral | J23: Support
A24: 18 - 24 | B24: 3 | C24: 29 | D24: 23 | E24: 55 | G24: 18 - 24 | H24: 0.054545455 | I24: 0.52727273 | J24: 0.41818182
A25: 25 - 29 | B25: 4 | C25: 45 | D25: 30 | E25: 79 | G25: 25 - 29 | H25: 0.050632911 | I25: 0.56962025 | J25: 0.37974684
A26: 30 - 39 | B26: 19 | C26: 76 | D26: 37 | E26: 132 | G26: 30 - 39 | H26: 0.14393939 | I26: 0.57575758 | J26: 0.28030303
A27: 40 - 49 | B27: 15 | C27: 43 | D27: 21 | E27: 79 | G27: 40 - 49 | H27: 0.18987342 | I27: 0.5443038 | J27: 0.26582278
A28: 50 - 54 | B28: 9 | C28: 11 | D28: 11 | E28: 31 | G28: 50 - 54 | H28: 0.29032258 | I28: 0.35483871 | J28: 0.35483871
A29: 55 - 64 | B29: 7 | C29: 14 | D29: 6 | E29: 27 | G29: 55 - 64 | H29: 0.25925926 | I29: 0.51851852 | J29: 0.22222222
A32: TRU2 | B32: Oppose | C32: Neutral | D32: Support | E32: =SUM(E33:E38) -> 403 | G32: TRU2 | H32: Oppose | I32: Neutral | J32: Support
A33: 18 - 24 | B33: 1 | C33: 14 | D33: 40 | E33: 55 | G33: 18 - 24 | H33: 0.018181818 | I33: 0.25454545 | J33: 0.72727273
A34: 25 - 29 | B34: 5 | C34: 33 | D34: 41 | E34: 79 | G34: 25 - 29 | H34: 0.063291139 | I34: 0.41772152 | J34: 0.51898734
A35: 30 - 39 | B35: 23 | C35: 66 | D35: 43 | E35: 132 | G35: 30 - 39 | H35: 0.17424242 | I35: 0.5 | J35: 0.32575758
A36: 40 - 49 | B36: 23 | C36: 35 | D36: 21 | E36: 79 | G36: 40 - 49 | H36: 0.29113924 | I36: 0.44303797 | J36: 0.26582278
A37: 50 - 54 | B37: 11 | C37: 15 | D37: 5 | E37: 31 | G37: 50 - 54 | H37: 0.35483871 | I37: 0.48387097 | J37: 0.16129032
A38: 55 - 64 | B38: 7 | C38: 15 | D38: 5 | E38: 27 | G38: 55 - 64 | H38: 0.25925926 | I38: 0.55555556 | J38: 0.18518519
A40: TRU3 | B40: Oppose | C40: Neutral | D40: Support | E40: =SUM(E41:E46) -> 403 | G40: TRU3 | H40: Oppose | I40: Neutral | J40: Support
A41: 18 - 24 | B41: 3 | C41: 28 | D41: 24 | E41: 55 | G41: 18 - 24 | H41: 0.054545455 | I41: 0.50909091 | J41: 0.43636364
A42: 25 - 29 | B42: 10 | C42: 46 | D42: 23 | E42: 79 | G42: 25 - 29 | H42: 0.12658228 | I42: 0.58227848 | J42: 0.29113924
A43: 30 - 39 | B43: 26 | C43: 71 | D43: 35 | E43: 132 | G43: 30 - 39 | H43: 0.1969697 | I43: 0.53787879 | J43: 0.26515152
A44: 40 - 49 | B44: 16 | C44: 45 | D44: 18 | E44: 79 | G44: 40 - 49 | H44: 0.20253165 | I44: 0.56962025 | J44: 0.2278481
A45: 50 - 54 | B45: 10 | C45: 14 | D45: 7 | E45: 31 | G45: 50 - 54 | H45: 0.32258065 | I45: 0.4516129 | J45: 0.22580645
A46: 55 - 64 | B46: 7 | C46: 13 | D46: 7 | E46: 27 | G46: 55 - 64 | H46: 0.25925926 | I46: 0.48148148 | J46: 0.25925926
A48: TRU4 | B48: Oppose | C48: Neutral | D48: Support | E48: =SUM(E49:E54) -> 403 | G48: TRU4 | H48: Oppose | I48: Neutral | J48: Support
...

Sheet Validation - Summary
A1: Validation - Summary
A2: Metric | B2: MAE (Intensity) | C2: Agreement Rate (%) | D2: MCC | E2: TVD | F2: EMD | G2: Human_Oppose (%) | H2: Human_Neutral (%) | I2: Human_Support (%) | J2: AI_Oppose (%) | K2: AI_Neutral (%) | L2: AI_Support (%)
A3: ENF1 | B3: =(B18+B32+B46+B60+B74)/5 -> 1.9151365 | C3: =(C18+C32+C46+C60+C74)/5 -> 0.43424318 | D3: =(D18+D32+D46+D60+D74)/5 -> 0.00097789611 | E3: =(E18+E32+E46+E60+E74)/5 -> 0.24218362 | F3: =(F18+F32+F46+F60+F74)/5 -> 0.95434243 | G3: =(G18+G32+G46+G60+G74)/5 -> 0.13647643 | H3: =(H18+H32+H46+H60+H74)/5 -> 0.44665012 | I3: =(I18+I32+I46+I60+I74)/5 -> 0.41687345 | ... L3: =(L18+L32+L46+L60+L74)/5 -> 0.29875931
A4: ENF2 | B4: =(B19+B33+B47+B61+B75)/5 -> 1.898263 | C4: =(C19+C33+C47+C61+C75)/5 -> 0.42452131 | D4: =(D19+D33+D47+D61+D75)/5 -> -0.027270302 | E4: =(E19+E33+E47+E61+E75)/5 -> 0.11092676 | F4: =(F19+F33+F47+F61+F75)/5 -> 0.73647643 | G4: =(G19+G33+G47+G61+G75)/5 -> 0.11166253 | H4: =(H19+H33+H47+H61+H75)/5 -> 0.41191067 | I4: =(I19+I33+I47+I61+I75)/5 -> 0.4764268 | ... L4: =(L19+L33+L47+L61+L75)/5 -> 0.4712023
A5: FAC1 | B5: =(B20+B34+B48+B62+B76)/5 -> 2.5975186 | C5: =(C20+C34+C48+C62+C76)/5 -> 0.3838043 | D5: =(D20+D34+D48+D62+D76)/5 -> 0.026828823 | E5: =(E20+E34+E48+E62+E76)/5 -> 0.44158365 | F5: =(F20+F34+F48+F62+F76)/5 -> 2.1890819 | G5: =(G20+G34+G48+G62+G76)/5 -> 0.20595533 | H5: =(H20+H34+H48+H62+H76)/5 -> 0.43920596 | I5: =(I20+I34+I48+I62+I76)/5 -> 0.35483871 | ... L5: =(L20+L34+L48+L62+L76)/5 -> 0.79642235
A6: FAC2 | B6: =(B21+B35+B49+B63+B77)/5 -> 1.8843672 | C6: =(C21+C35+C49+C63+C77)/5 -> 0.49254842 | D6: =(D21+D35+D49+D63+D77)/5 -> 0.025662422 | E6: =(E21+E35+E49+E63+E77)/5 -> 0.47442934 | F6: =(F21+F35+F49+F63+F77)/5 -> 1.546402 | G6: =(G21+G35+G49+G63+G77)/5 -> 0.052109181 | H6: =(H21+H35+H49+H63+H77)/5 -> 0.45905707 | I6: =(I21+I35+I49+I63+I77)/5 -> 0.48883375 | ... L6: =(L21+L35+L49+L63+L77)/5 -> 0.96326309
A7: TRU1 | B7: =(B22+B36+B50+B64+B78)/5 -> 2.1002481 | C7: =(C22+C36+C50+C64+C78)/5 -> 0.43547971 | D7: =(D22+D36+D50+D64+D78)/5 -> 0.028032426 | E7: =(E22+E36+E50+E64+E78)/5 -> 0.2164971 | F7: =(F22+F36+F50+F64+F78)/5 -> 1.4168734 | G7: =(G22+G36+G50+G64+G78)/5 -> 0.14143921 | H7: =(H22+H36+H50+H64+H78)/5 -> 0.54094293 | I7: =(I22+I36+I50+I64+I78)/5 -> 0.31761787 | ... L7: =(L22+L36+L50+L64+L78)/5 -> 0.53411496
A8: TRU2 | B8: =(B23+B37+B51+B65+B79)/5 -> 2.462531 | C8: =(C23+C37+C51+C65+C79)/5 -> 0.37866404 | D8: =(D23+D37+D51+D65+D79)/5 -> -0.027899709 | E8: =(E23+E37+E51+E65+E79)/5 -> 0.57053157 | F8: =(F23+F37+F51+F65+F79)/5 -> 2.169727 | G8: =(G23+G37+G51+G65+G79)/5 -> 0.17369727 | H8: =(H23+H37+H51+H65+H79)/5 -> 0.44168734 | I8: =(I23+I37+I51+I65+I79)/5 -> 0.38461538 | ... L8: =(L23+L37+L51+L65+L79)/5 -> 0.95514696
A9: TRU3 | B9: =(B24+B38+B52+B66+B80)/5 -> 2.462531 | C9: =(C24+C38+C52+C66+C80)/5 -> 0.40009057 | D9: =(D24+D38+D52+D66+D80)/5 -> 0.019436244 | E9: =(E24+E38+E52+E66+E80)/5 -> 0.2980784 | F9: =(F24+F38+F52+F66+F80)/5 -> 1.88933 | G9: =(G24+G38+G52+G66+G80)/5 -> 0.17866005 | H9: =(H24+H38+H52+H66+H80)/5 -> 0.53846154 | I9: =(I24+I38+I52+I66+I80)/5 -> 0.28287841 | ... L9: =(L24+L38+L52+L66+L80)/5 -> 0.58095681
A10: TRU4 | B10: =(B25+B39+B53+B67+B81)/5 -> 1.9776675 | C10: =(C25+C39+C53+C67+C81)/5 -> 0.43646233 | D10: =(D25+D39+D53+D67+D81)/5 -> 6.0542354e-05 | E10: =(E25+E39+E53+E67+E81)/5 -> 0.22042527 | F10: =(F25+F39+F53+F67+F81)/5 -> 1.2610422 | G10: =(G25+G39+G53+G67+G81)/5 -> 0.11414392 | H10: =(H25+H39+H53+H67+H81)/5 -> 0.58312655 | I10: =(I25+I39+I53+I67+I81)/5 -> 0.30272953 | ... L10: =(L25+L39+L53+L67+L81)/5 -> 0.5231548
A11: OUT1 | B11: =(B26+B40+B54+B68+B82)/5 -> 2.2486352 | C11: =(C26+C40+C54+C68+C82)/5 -> 0.43669046 | D11: =(D26+D40+D54+D68+D82)/5 -> 0.014769023 | E11: =(E26+E40+E54+E68+E82)/5 -> 0.52734778 | F11: =(F26+F40+F54+F68+F82)/5 -> 1.9225806 | G11: =(G26+G40+G54+G68+G82)/5 -> 0.086848635 | H11: =(H26+H40+H54+H68+H82)/5 -> 0.48138958 | I11: =(I26+I40+I54+I68+I82)/5 -> 0.43176179 | ... L11: =(L26+L40+L54+L68+L82)/5 -> 0.95910956
A12: AIx | B12: =(B27+B41+B55+B69+B83)/5 -> 0.75494899
A13: OUT1 score | B13: =(B28+B42+B56+B70+B84)/5 -> 0.85304659
A16: Validation - Run 1
A17: Metric | B17: MAE (Intensity) | C17: Agreement Rate (%) | D17: MCC | E17: TVD | F17: EMD | G17: Human_Oppose (%) | H17: Human_Neutral (%) | I17: Human_Support (%) | J17: AI_Oppose (%) | K17: AI_Neutral (%) | L17: AI_Support (%)
A18: ENF1 | B18: 1.9478908 | C18: 0.42679901 | D18: -0.011988784 | E18: 0.23573201 | F18: 0.96277916 | G18: 0.13647643 | H18: 0.44665012 | I18: 0.41687345 | J18: 0.014888337 | K18: 0.68238213 | L18: 0.30272953
A19: ENF2 | B19: 1.9454094 | C19: 0.41044776 | D19: -0.052666491 | E19: 0.10550227 | F19: 0.74193548 | G19: 0.11166253 | H19: 0.41191067 | I19: 0.4764268 | J19: 0.0099502488 | K19: 0.51741294 | L19: 0.47263682
A20: FAC1 | B20: 2.6277916 | C20: 0.36567164 | D20: -0.014395225 | E20: 0.43620607 | F20: 2.1885856 | G20: 0.20595533 | H20: 0.43920596 | I20: 0.35483871 | J20: 0.0024875622 | K20: 0.20646766 | L20: 0.79104478
A21: FAC2 | B21: 1.8808933 | C21: 0.48507463 | D21: -0.011084069 | E21: 0.48629063 | F21: 1.5558313 | G21: 0.052109181 | H21: 0.45905707 | I21: 0.48883375 | J21: 0 | K21: 0.024875622 | L21: 0.97512438
A22: TRU1 | B22: 2.1066998 | C22: 0.44029851 | D22: 0.03704103 | E22: 0.22218313 | F22: 1.4069479 | G22: 0.14143921 | H22: 0.54094293 | I22: 0.31761787 | J22: 0 | K22: 0.460199 | L22: 0.539801
A23: TRU2 | B23: 2.4218362 | C23: 0.40049751 | D23: 0.073493366 | E23: 0.58802143 | F23: 2.1687345 | G23: 0.17369727 | H23: 0.44168734 | I23: 0.38461538 | J23: 0 | K23: 0.027363184 | L23: 0.97263682
A24: TRU3 | B24: 2.4789082 | C24: 0.4079602 | D24: 0.036131241 | E24: 0.30418626 | F24: 1.8858561 | G24: 0.17866005 | H24: 0.53846154 | I24: 0.28287841 | J24: 0.0024875622 | K24: 0.41044776 | L24: 0.58706468
A25: TRU4 | B25: 1.9727047 | C25: 0.42288557 | D25: -0.015453522 | E25: 0.23955903 | F25: 1.2605459 | G25: 0.11414392 | H25: 0.58312655 | I25: 0.30272953 | J25: 0 | K25: 0.45771144 | L25: 0.54228856
A26: OUT1 | B26: 2.2679901 | C26: 0.44029851 | D26: 0.031293693 | E26: 0.5358999 | F26: 1.91067 | G26: 0.086848635 | H26: 0.48138958 | I26: 0.43176179 | J26: 0 | K26: 0.032338308 | L26: 0.96766169
A27: AIx | B27: 0.75521551
A28: OUT1 score | B28: 0.85663082
A30: Validation - Run 2
A31: Metric | B31: MAE (Intensity) | C31: Agreement Rate (%) | D31: MCC | E31: TVD | F31: EMD | G31: Human_Oppose (%) | H31: Human_Neutral (%) | I31: Human_Support (%) | J31: AI_Oppose (%) | K31: AI_Neutral (%) | L31: AI_Support (%)
A32: ENF1 | B32: 1.8585608 | C32: 0.46401985 | D32: 0.053237789 | E32: 0.27047146 | F32: 0.92059553 | G32: 0.13647643 | H32: 0.44665012 | I32: 0.41687345 | J32: 0.0024813896 | K32: 0.71712159 | L32: 0.28039702
A33: ENF2 | B33: 1.8883375 | C33: 0.43920596 | D33: -0.0027901254 | E33: 0.10421836 | F33: 0.7146402 | G33: 0.11166253 | H33: 0.41191067 | I33: 0.4764268 | J33: 0.0074441687 | K33: 0.51116625 | L33: 0.48138958
A34: FAC1 | B34: 2.573201 | C34: 0.38461538 | D34: 0.021125567 | E34: 0.41191067 | F34: 2.191067 | G34: 0.20595533 | H34: 0.43920596 | I34: 0.35483871 | J34: 0 | K34: 0.23325062 | L34: 0.76674938
A35: FAC2 | B35: 1.9131514 | C35: 0.48883375 | D35: 0.005785446 | E35: 0.47146402 | F35: 1.5086849 | G35: 0.052109181 | H35: 0.45905707 | I35: 0.48883375 | J35: 0 | K35: 0.039702233 | L35: 0.96029777
A36: TRU1 | B36: 2.0024814 | C36: 0.43890274 | D36: 0.015352542 | E36: 0.17614772 | F36: 1.4565757 | G36: 0.14143921 | H36: 0.54094293 | I36: 0.31761787 | J36: 0.0024937656 | K36: 0.50374065 | L36: 0.49376559
A37: TRU2 | B37: 2.4739454 | C37: 0.37406484 | D37: -0.052597954 | E37: 0.56301554 | F37: 2.1736973 | G37: 0.17369727 | H37: 0.44168734 | I37: 0.38461538 | J37: 0 | K37: 0.052369077 | L37: 0.94763092
A38: TRU3 | B38: 2.4069479 | C38: 0.37905237 | D38: -0.029957472 | E38: 0.28071261 | F38: 1.9032258 | G38: 0.17866005 | H38: 0.53846154 | I38: 0.28287841 | J38: 0 | K38: 0.43640898 | L38: 0.56359102
A39: TRU4 | B39: 1.9875931 | C39: 0.43142145 | D39: -0.028437798 | E39: 0.18854229 | F39: 1.2630273 | G39: 0.11414392 | H39: 0.58312655 | I39: 0.30272953 | J39: 0 | K39: 0.50872818 | L39: 0.49127182
A40: OUT1 | B40: 2.2059553 | C40: 0.43890274 | D40: 0.024020845 | E40: 0.51586914 | F40: 1.9702233 | G40: 0.086848635 | H40: 0.48138958 | I40: 0.43176179 | J40: 0.0024937656 | K40: 0.049875312 | L40: 0.94763092
A41: AIx | B41: 0.75227461
A42: OUT1 score | B42: 0.84642956
A44: Validation - Run 3
...

Sheet Calibration - Summary
A1: Calibration - Summary
A2: Metric | B2: MAE (Intensity) | C2: Agreement Rate (%) | D2: MCC | E2: TVD | F2: EMD | G2: Human_Oppose (%) | H2: Human_Neutral (%) | I2: Human_Support (%) | J2: AI_Oppose (%) | K2: AI_Neutral (%) | L2: AI_Support (%)
A3: ENF1 | B3: =(B18+B32+B46+B60+B74)/5 -> 1.8471464 | C3: =(C18+C32+C46+C60+C74)/5 -> 0.43473945 | D3: =(D18+D32+D46+D60+D74)/5 -> 0.00097132092 | E3: =(E18+E32+E46+E60+E74)/5 -> 0.23970223 | F3: =(F18+F32+F46+F60+F74)/5 -> 1.4143921 | G3: =(G18+G32+G46+G60+G74)/5 -> 0.13647643 | H3: =(H18+H32+H46+H60+H74)/5 -> 0.44665012 | I3: =(I18+I32+I46+I60+I74)/5 -> 0.41687345 | ... L3: =(L18+L32+L46+L60+L74)/5 -> 0.30173697
A4: ENF2 | B4: =(B19+B33+B47+B61+B75)/5 -> 1.8377171 | C4: =(C19+C33+C47+C61+C75)/5 -> 0.45856079 | D4: =(D19+D33+D47+D61+D75)/5 -> 0.033905287 | E4: =(E19+E33+E47+E61+E75)/5 -> 0.1439206 | F4: =(F19+F33+F47+F61+F75)/5 -> 1.6401985 | G4: =(G19+G33+G47+G61+G75)/5 -> 0.11166253 | H4: =(H19+H33+H47+H61+H75)/5 -> 0.41191067 | I4: =(I19+I33+I47+I61+I75)/5 -> 0.4764268 | ... L4: =(L19+L33+L47+L61+L75)/5 -> 0.44764268
A5: FAC1 | B5: =(B20+B34+B48+B62+B76)/5 -> 2.4456576 | C5: =(C20+C34+C48+C62+C76)/5 -> 0.39007444 | D5: =(D20+D34+D48+D62+D76)/5 -> 0.0091640253 | E5: =(E20+E34+E48+E62+E76)/5 -> 0.25756824 | F5: =(F20+F34+F48+F62+F76)/5 -> 1.9255583 | G5: =(G20+G34+G48+G62+G76)/5 -> 0.20595533 | H5: =(H20+H34+H48+H62+H76)/5 -> 0.43920596 | I5: =(I20+I34+I48+I62+I76)/5 -> 0.35483871 | ... L5: =(L20+L34+L48+L62+L76)/5 -> 0.60942928
A6: FAC2 | B6: =(B21+B35+B49+B63+B77)/5 -> 1.6908189 | C6: =(C21+C35+C49+C63+C77)/5 -> 0.46423466 | D6: =(D21+D35+D49+D63+D77)/5 -> -0.021171245 | E6: =(E21+E35+E49+E63+E77)/5 -> 0.18943002 | F6: =(F21+F35+F49+F63+F77)/5 -> 0.75682382 | G6: =(G21+G35+G49+G63+G77)/5 -> 0.052109181 | H6: =(H21+H35+H49+H63+H77)/5 -> 0.45905707 | I6: =(I21+I35+I49+I63+I77)/5 -> 0.48883375 | ... L6: =(L21+L35+L49+L63+L77)/5 -> 0.67826377
A7: TRU1 | B7: =(B22+B36+B50+B64+B78)/5 -> 2.0099256 | C7: =(C22+C36+C50+C64+C78)/5 -> 0.45035739 | D7: =(D22+D36+D50+D64+D78)/5 -> -0.018752202 | E7: =(E22+E36+E50+E64+E78)/5 -> 0.12108811 | F7: =(F22+F36+F50+F64+F78)/5 -> 0.8808933 | G7: =(G22+G36+G50+G64+G78)/5 -> 0.14143921 | H7: =(H22+H36+H50+H64+H78)/5 -> 0.54094293 | I7: =(I22+I36+I50+I64+I78)/5 -> 0.31761787 | ... L7: =(L22+L36+L50+L64+L78)/5 -> 0.31827463
A8: TRU2 | B8: =(B23+B37+B51+B65+B79)/5 -> 2.0818859 | C8: =(C23+C37+C51+C65+C79)/5 -> 0.42800637 | D8: =(D23+D37+D51+D65+D79)/5 -> 0.016688063 | E8: =(E23+E37+E51+E65+E79)/5 -> 0.22563732 | F8: =(F23+F37+F51+F65+F79)/5 -> 1.101737 | G8: =(G23+G37+G51+G65+G79)/5 -> 0.17369727 | H8: =(H23+H37+H51+H65+H79)/5 -> 0.44168734 | I8: =(I23+I37+I51+I65+I79)/5 -> 0.38461538 | ... L8: =(L23+L37+L51+L65+L79)/5 -> 0.31530067
A9: TRU3 | B9: =(B24+B38+B52+B66+B80)/5 -> 2.1756824 | C9: =(C24+C38+C52+C66+C80)/5 -> 0.47020974 | D9: =(D24+D38+D52+D66+D80)/5 -> -0.028228239 | E9: =(E24+E38+E52+E66+E80)/5 -> 0.25974421 | F9: =(F24+F38+F52+F66+F80)/5 -> 1.2382134 | G9: =(G24+G38+G52+G66+G80)/5 -> 0.17866005 | H9: =(H24+H38+H52+H66+H80)/5 -> 0.53846154 | I9: =(I24+I38+I52+I66+I80)/5 -> 0.28287841 | ... L9: =(L24+L38+L52+L66+L80)/5 -> 0.15805749
A10: TRU4 | B10: =(B25+B39+B53+B67+B81)/5 -> 1.8764268 | C10: =(C25+C39+C53+C67+C81)/5 -> 0.5432269 | D10: =(D25+D39+D53+D67+D81)/5 -> 0.030646532 | E10: =(E25+E39+E53+E67+E81)/5 -> 0.27372531 | F10: =(F25+F39+F53+F67+F81)/5 -> 0.79404467 | G10: =(G25+G39+G53+G67+G81)/5 -> 0.11414392 | H10: =(H25+H39+H53+H67+H81)/5 -> 0.58312655 | I10: =(I25+I39+I53+I67+I81)/5 -> 0.30272953 | ... L10: =(L25+L39+L53+L67+L81)/5 -> 0.08250703
A11: OUT1 | B11: =(B26+B40+B54+B68+B82)/5 -> 1.8987593 | C11: =(C26+C40+C54+C68+C82)/5 -> 0.45786018 | D11: =(D26+D40+D54+D68+D82)/5 -> 0.0017808799 | E11: =(E26+E40+E54+E68+E82)/5 -> 0.15515481 | F11: =(F26+F40+F54+F68+F82)/5 -> 0.66253102 | G11: =(G26+G40+G54+G68+G82)/5 -> 0.086848635 | H11: =(H26+H40+H54+H68+H82)/5 -> 0.48138958 | I11: =(I26+I40+I54+I68+I82)/5 -> 0.43176179 | ... L11: =(L26+L40+L54+L68+L82)/5 -> 0.34448917
A12: AIx | B12: =(B27+B41+B55+B69+B83)/5 -> 0.68159636
A13: OUT1 score | B13: =(B28+B42+B56+B70+B84)/5 -> 0.66594982
A16: Calibration - Run 1
A17: Metric | B17: MAE (Intensity) | C17: Agreement Rate (%) | D17: MCC | E17: TVD | F17: EMD | G17: Human_Oppose (%) | H17: Human_Neutral (%) | I17: Human_Support (%) | J17: AI_Oppose (%) | K17: AI_Neutral (%) | L17: AI_Support (%)
A18: ENF1 | B18: 1.8039702 | C18: 0.48138958 | D18: 0.093010708 | E18: 0.22332506 | F18: 1.4143921 | G18: 0.13647643 | H18: 0.44665012 | I18: 0.41687345 | J18: 0.014888337 | K18: 0.66997519 | L18: 0.31513648
A19: ENF2 | B19: 1.7890819 | C19: 0.48387097 | D19: 0.084198309 | E19: 0.15136476 | F19: 1.6401985 | G19: 0.11166253 | H19: 0.41191067 | I19: 0.4764268 | J19: 0.0049627792 | K19: 0.56327543 | L19: 0.43176179
A20: FAC1 | B20: 2.3995037 | C20: 0.40694789 | D20: 0.040300136 | E20: 0.27543424 | F20: 1.9255583 | G20: 0.20595533 | H20: 0.43920596 | I20: 0.35483871 | J20: 0.0049627792 | K20: 0.36476427 | L20: 0.63027295
A21: FAC2 | B21: 1.7270471 | C21: 0.45905707 | D21: -0.028759162 | E21: 0.191067 | F21: 0.75682382 | G21: 0.052109181 | H21: 0.45905707 | I21: 0.48883375 | J21: 0.014888337 | K21: 0.30521092 | L21: 0.67990074
A22: TRU1 | B22: 1.9379653 | C22: 0.46650124 | D22: 0.011589134 | E22: 0.12406948 | F22: 0.8808933 | G22: 0.14143921 | H22: 0.54094293 | I22: 0.31761787 | J22: 0.032258065 | K22: 0.66501241 | L22: 0.30272953
A23: TRU2 | B23: 2.1116625 | C23: 0.42431762 | D23: 0.011552039 | E23: 0.22828784 | F23: 1.101737 | G23: 0.17369727 | H23: 0.44168734 | I23: 0.38461538 | J23: 0.022332506 | K23: 0.66997519 | L23: 0.30769231
A24: TRU3 | B24: 2.133995 | C24: 0.46650124 | D24: -0.021378734 | E24: 0.2382134 | F24: 1.2382134 | G24: 0.17866005 | H24: 0.53846154 | I24: 0.28287841 | J24: 0.047146402 | K24: 0.77667494 | L24: 0.17617866
A25: TRU4 | B25: 1.8858561 | C25: 0.55583127 | D25: 0.069287351 | E25: 0.27295285 | F25: 0.79404467 | G25: 0.11414392 | H25: 0.58312655 | I25: 0.30272953 | J25: 0.069478908 | K25: 0.8560794 | L25: 0.074441687
A26: OUT1 | B26: 1.8808933 | C26: 0.44389027 | D26: -0.026324753 | E26: 0.13706429 | F26: 0.66253102 | G26: 0.086848635 | H26: 0.48138958 | I26: 0.43176179 | J26: 0.017456359 | K26: 0.61845387 | L26: 0.36408978
A27: AIx | B27: 0.68254296
A28: OUT1 score | B28: 0.67190516
A30: Calibration - Run 2
A31: Metric | B31: MAE (Intensity) | C31: Agreement Rate (%) | D31: MCC | E31: TVD | F31: EMD | G31: Human_Oppose (%) | H31: Human_Neutral (%) | I31: Human_Support (%) | J31: AI_Oppose (%) | K31: AI_Neutral (%) | L31: AI_Support (%)
A32: ENF1 | B32: 1.8610422 | C32: 0.43424318 | D32: -0.0013104163 | E32: 0.27543424 | F32: 1.4143921 | G32: 0.13647643 | H32: 0.44665012 | I32: 0.41687345 | J32: 0.012406948 | K32: 0.72208437 | L32: 0.26550868
A33: ENF2 | B33: 1.8858561 | C33: 0.42679901 | D33: -0.022961089 | E33: 0.1662531 | F33: 1.6401985 | G33: 0.11166253 | H33: 0.41191067 | I33: 0.4764268 | J33: 0 | K33: 0.57816377 | L33: 0.42183623
A34: FAC1 | B34: 2.4789082 | C34: 0.38709677 | D34: 0.0086161535 | E34: 0.27791563 | F34: 1.9255583 | G34: 0.20595533 | H34: 0.43920596 | I34: 0.35483871 | J34: 0.014888337 | K34: 0.35235732 | L34: 0.63275434
A35: FAC2 | B35: 1.6377171 | C35: 0.49131514 | D35: 0.0310007 | E35: 0.18114144 | F35: 0.75682382 | G35: 0.052109181 | H35: 0.45905707 | I35: 0.48883375 | J35: 0.0074441687 | K35: 0.32258065 | L35: 0.66997519
A36: TRU1 | B36: 2.0471464 | C36: 0.41439206 | D36: -0.084030117 | E36: 0.11414392 | F36: 0.8808933 | G36: 0.14143921 | H36: 0.54094293 | I36: 0.31761787 | J36: 0.027295285 | K36: 0.65260546 | L36: 0.32009926
A37: TRU2 | B37: 2.0794045 | C37: 0.41687345 | D37: -0.0040706782 | E37: 0.22580645 | F37: 1.101737 | G37: 0.17369727 | H37: 0.44168734 | I37: 0.38461538 | J37: 0.017369727 | K37: 0.6674938 | L37: 0.31513648
A38: TRU3 | B38: 2.1836228 | C38: 0.46153846 | D38: -0.056859949 | E38: 0.27543424 | F38: 1.2382134 | G38: 0.17866005 | H38: 0.53846154 | I38: 0.28287841 | J38: 0.044665012 | K38: 0.81389578 | L38: 0.14143921
A39: TRU4 | B39: 1.8808933 | C39: 0.5483871 | D39: 0.034633166 | E39: 0.28287841 | F39: 0.79404467 | G39: 0.11414392 | H39: 0.58312655 | I39: 0.30272953 | J39: 0.052109181 | K39: 0.86600496 | L39: 0.081885856
A40: OUT1 | B40: 1.942928 | C40: 0.43890274 | D40: -0.034221997 | E40: 0.17696454 | F40: 0.66253102 | G40: 0.086848635 | H40: 0.48138958 | I40: 0.43176179 | J40: 0.019950125 | K40: 0.65835411 | L40: 0.32169576
A41: AIx | B41: 0.67911957
A42: OUT1 score | B42: 0.66060105
A44: Calibration - Run 3
...
